2025-07-22 05:45:25 - error_handlers - DEBUG - Logger initialized for error_handlers at level DEBUG
2025-07-22 05:45:25 - error_handlers - INFO - Initializing error handling module
2025-07-22 05:45:28 - error_handlers - INFO - Initializing error handling module
2025-07-22 06:40:57 - error_handlers - ERROR - Error in get_all_currencies: (mysql.connector.errors.OperationalError) MySQL Connection not available.
[SQL: SELECT currencies.`CurrencyID` AS `currencies_CurrencyID`, currencies.`CurrencyName` AS `currencies_CurrencyName`, currencies.`Icon` AS `currencies_Icon`, currencies.`Symbol` AS `currencies_Symbol`, currencies.`BlockchainID` AS `currencies_BlockchainID`, currencies.`DecimalPlaces` AS `currencies_DecimalPlaces`, currencies.`IsToken` AS `currencies_IsToken`, currencies.`SmartContractAddress` AS `currencies_SmartContractAddress`, currencies.`CreatedAt` AS `currencies_CreatedAt`, currencies.`UpdatedAt` AS `currencies_UpdatedAt`, currencies.`CMC_ID` AS `currencies_CMC_ID`, blockchains.`BlockchainName` AS `blockchains_BlockchainName` 
FROM currencies INNER JOIN blockchains ON currencies.`BlockchainID` = blockchains.`BlockchainID`]
[parameters: [{}]]
(Background on this error at: https://sqlalche.me/e/20/e3q8)
Traceback (most recent call last):
  File "/www/wwwroot/coinceeper.com/CC/venv/lib64/python3.9/site-packages/sqlalchemy/engine/base.py", line 1811, in _execute_context
    context = constructor(
  File "/www/wwwroot/coinceeper.com/CC/venv/lib64/python3.9/site-packages/sqlalchemy/engine/default.py", line 1427, in _init_compiled
    self.cursor = self.create_cursor()
  File "/www/wwwroot/coinceeper.com/CC/venv/lib64/python3.9/site-packages/sqlalchemy/engine/default.py", line 1766, in create_cursor
    return self.create_default_cursor()
  File "/www/wwwroot/coinceeper.com/CC/venv/lib64/python3.9/site-packages/sqlalchemy/dialects/mysql/mysqlconnector.py", line 67, in create_default_cursor
    return self._dbapi_connection.cursor(buffered=True)
  File "/www/wwwroot/coinceeper.com/CC/venv/lib64/python3.9/site-packages/sqlalchemy/pool/base.py", line 1486, in cursor
    return self.dbapi_connection.cursor(*args, **kwargs)
  File "/www/wwwroot/coinceeper.com/CC/venv/lib64/python3.9/site-packages/mysql/connector/connection_cext.py", line 841, in cursor
    raise OperationalError("MySQL Connection not available.")
mysql.connector.errors.OperationalError: MySQL Connection not available.

The above exception was the direct cause of the following exception:

Traceback (most recent call last):
  File "/www/wwwroot/coinceeper.com/CC/utils/error_handlers.py", line 119, in decorated_function
    return f(*args, **kwargs)
  File "/www/wwwroot/coinceeper.com/CC/Currencies/All_Currencies.py", line 46, in get_all_currencies
    currencies_query = session.query(
  File "/www/wwwroot/coinceeper.com/CC/venv/lib64/python3.9/site-packages/sqlalchemy/orm/query.py", line 2704, in all
    return self._iter().all()  # type: ignore
  File "/www/wwwroot/coinceeper.com/CC/venv/lib64/python3.9/site-packages/sqlalchemy/orm/query.py", line 2857, in _iter
    result: Union[ScalarResult[_T], Result[_T]] = self.session.execute(
  File "/www/wwwroot/coinceeper.com/CC/venv/lib64/python3.9/site-packages/sqlalchemy/orm/session.py", line 2365, in execute
    return self._execute_internal(
  File "/www/wwwroot/coinceeper.com/CC/venv/lib64/python3.9/site-packages/sqlalchemy/orm/session.py", line 2251, in _execute_internal
    result: Result[Any] = compile_state_cls.orm_execute_statement(
  File "/www/wwwroot/coinceeper.com/CC/venv/lib64/python3.9/site-packages/sqlalchemy/orm/context.py", line 306, in orm_execute_statement
    result = conn.execute(
  File "/www/wwwroot/coinceeper.com/CC/venv/lib64/python3.9/site-packages/sqlalchemy/engine/base.py", line 1415, in execute
    return meth(
  File "/www/wwwroot/coinceeper.com/CC/venv/lib64/python3.9/site-packages/sqlalchemy/sql/elements.py", line 523, in _execute_on_connection
    return connection._execute_clauseelement(
  File "/www/wwwroot/coinceeper.com/CC/venv/lib64/python3.9/site-packages/sqlalchemy/engine/base.py", line 1637, in _execute_clauseelement
    ret = self._execute_context(
  File "/www/wwwroot/coinceeper.com/CC/venv/lib64/python3.9/site-packages/sqlalchemy/engine/base.py", line 1817, in _execute_context
    self._handle_dbapi_exception(
  File "/www/wwwroot/coinceeper.com/CC/venv/lib64/python3.9/site-packages/sqlalchemy/engine/base.py", line 2351, in _handle_dbapi_exception
    raise sqlalchemy_exception.with_traceback(exc_info[2]) from e
  File "/www/wwwroot/coinceeper.com/CC/venv/lib64/python3.9/site-packages/sqlalchemy/engine/base.py", line 1811, in _execute_context
    context = constructor(
  File "/www/wwwroot/coinceeper.com/CC/venv/lib64/python3.9/site-packages/sqlalchemy/engine/default.py", line 1427, in _init_compiled
    self.cursor = self.create_cursor()
  File "/www/wwwroot/coinceeper.com/CC/venv/lib64/python3.9/site-packages/sqlalchemy/engine/default.py", line 1766, in create_cursor
    return self.create_default_cursor()
  File "/www/wwwroot/coinceeper.com/CC/venv/lib64/python3.9/site-packages/sqlalchemy/dialects/mysql/mysqlconnector.py", line 67, in create_default_cursor
    return self._dbapi_connection.cursor(buffered=True)
  File "/www/wwwroot/coinceeper.com/CC/venv/lib64/python3.9/site-packages/sqlalchemy/pool/base.py", line 1486, in cursor
    return self.dbapi_connection.cursor(*args, **kwargs)
  File "/www/wwwroot/coinceeper.com/CC/venv/lib64/python3.9/site-packages/mysql/connector/connection_cext.py", line 841, in cursor
    raise OperationalError("MySQL Connection not available.")
sqlalchemy.exc.OperationalError: (mysql.connector.errors.OperationalError) MySQL Connection not available.
[SQL: SELECT currencies.`CurrencyID` AS `currencies_CurrencyID`, currencies.`CurrencyName` AS `currencies_CurrencyName`, currencies.`Icon` AS `currencies_Icon`, currencies.`Symbol` AS `currencies_Symbol`, currencies.`BlockchainID` AS `currencies_BlockchainID`, currencies.`DecimalPlaces` AS `currencies_DecimalPlaces`, currencies.`IsToken` AS `currencies_IsToken`, currencies.`SmartContractAddress` AS `currencies_SmartContractAddress`, currencies.`CreatedAt` AS `currencies_CreatedAt`, currencies.`UpdatedAt` AS `currencies_UpdatedAt`, currencies.`CMC_ID` AS `currencies_CMC_ID`, blockchains.`BlockchainName` AS `blockchains_BlockchainName` 
FROM currencies INNER JOIN blockchains ON currencies.`BlockchainID` = blockchains.`BlockchainID`]
[parameters: [{}]]
(Background on this error at: https://sqlalche.me/e/20/e3q8)
2025-07-22 06:40:57 - error_handlers - ERROR - Database connection error: (mysql.connector.errors.OperationalError) MySQL Connection not available.
[SQL: SELECT currencies.`CurrencyID` AS `currencies_CurrencyID`, currencies.`CurrencyName` AS `currencies_CurrencyName`, currencies.`Icon` AS `currencies_Icon`, currencies.`Symbol` AS `currencies_Symbol`, currencies.`BlockchainID` AS `currencies_BlockchainID`, currencies.`DecimalPlaces` AS `currencies_DecimalPlaces`, currencies.`IsToken` AS `currencies_IsToken`, currencies.`SmartContractAddress` AS `currencies_SmartContractAddress`, currencies.`CreatedAt` AS `currencies_CreatedAt`, currencies.`UpdatedAt` AS `currencies_UpdatedAt`, currencies.`CMC_ID` AS `currencies_CMC_ID`, blockchains.`BlockchainName` AS `blockchains_BlockchainName` 
FROM currencies INNER JOIN blockchains ON currencies.`BlockchainID` = blockchains.`BlockchainID`]
[parameters: [{}]]
(Background on this error at: https://sqlalche.me/e/20/e3q8)
Traceback (most recent call last):
  File "/www/wwwroot/coinceeper.com/CC/venv/lib64/python3.9/site-packages/sqlalchemy/engine/base.py", line 1811, in _execute_context
    context = constructor(
  File "/www/wwwroot/coinceeper.com/CC/venv/lib64/python3.9/site-packages/sqlalchemy/engine/default.py", line 1427, in _init_compiled
    self.cursor = self.create_cursor()
  File "/www/wwwroot/coinceeper.com/CC/venv/lib64/python3.9/site-packages/sqlalchemy/engine/default.py", line 1766, in create_cursor
    return self.create_default_cursor()
  File "/www/wwwroot/coinceeper.com/CC/venv/lib64/python3.9/site-packages/sqlalchemy/dialects/mysql/mysqlconnector.py", line 67, in create_default_cursor
    return self._dbapi_connection.cursor(buffered=True)
  File "/www/wwwroot/coinceeper.com/CC/venv/lib64/python3.9/site-packages/sqlalchemy/pool/base.py", line 1486, in cursor
    return self.dbapi_connection.cursor(*args, **kwargs)
  File "/www/wwwroot/coinceeper.com/CC/venv/lib64/python3.9/site-packages/mysql/connector/connection_cext.py", line 841, in cursor
    raise OperationalError("MySQL Connection not available.")
mysql.connector.errors.OperationalError: MySQL Connection not available.

The above exception was the direct cause of the following exception:

Traceback (most recent call last):
  File "/www/wwwroot/coinceeper.com/CC/utils/error_handlers.py", line 119, in decorated_function
    return f(*args, **kwargs)
  File "/www/wwwroot/coinceeper.com/CC/Currencies/All_Currencies.py", line 46, in get_all_currencies
    currencies_query = session.query(
  File "/www/wwwroot/coinceeper.com/CC/venv/lib64/python3.9/site-packages/sqlalchemy/orm/query.py", line 2704, in all
    return self._iter().all()  # type: ignore
  File "/www/wwwroot/coinceeper.com/CC/venv/lib64/python3.9/site-packages/sqlalchemy/orm/query.py", line 2857, in _iter
    result: Union[ScalarResult[_T], Result[_T]] = self.session.execute(
  File "/www/wwwroot/coinceeper.com/CC/venv/lib64/python3.9/site-packages/sqlalchemy/orm/session.py", line 2365, in execute
    return self._execute_internal(
  File "/www/wwwroot/coinceeper.com/CC/venv/lib64/python3.9/site-packages/sqlalchemy/orm/session.py", line 2251, in _execute_internal
    result: Result[Any] = compile_state_cls.orm_execute_statement(
  File "/www/wwwroot/coinceeper.com/CC/venv/lib64/python3.9/site-packages/sqlalchemy/orm/context.py", line 306, in orm_execute_statement
    result = conn.execute(
  File "/www/wwwroot/coinceeper.com/CC/venv/lib64/python3.9/site-packages/sqlalchemy/engine/base.py", line 1415, in execute
    return meth(
  File "/www/wwwroot/coinceeper.com/CC/venv/lib64/python3.9/site-packages/sqlalchemy/sql/elements.py", line 523, in _execute_on_connection
    return connection._execute_clauseelement(
  File "/www/wwwroot/coinceeper.com/CC/venv/lib64/python3.9/site-packages/sqlalchemy/engine/base.py", line 1637, in _execute_clauseelement
    ret = self._execute_context(
  File "/www/wwwroot/coinceeper.com/CC/venv/lib64/python3.9/site-packages/sqlalchemy/engine/base.py", line 1817, in _execute_context
    self._handle_dbapi_exception(
  File "/www/wwwroot/coinceeper.com/CC/venv/lib64/python3.9/site-packages/sqlalchemy/engine/base.py", line 2351, in _handle_dbapi_exception
    raise sqlalchemy_exception.with_traceback(exc_info[2]) from e
  File "/www/wwwroot/coinceeper.com/CC/venv/lib64/python3.9/site-packages/sqlalchemy/engine/base.py", line 1811, in _execute_context
    context = constructor(
  File "/www/wwwroot/coinceeper.com/CC/venv/lib64/python3.9/site-packages/sqlalchemy/engine/default.py", line 1427, in _init_compiled
    self.cursor = self.create_cursor()
  File "/www/wwwroot/coinceeper.com/CC/venv/lib64/python3.9/site-packages/sqlalchemy/engine/default.py", line 1766, in create_cursor
    return self.create_default_cursor()
  File "/www/wwwroot/coinceeper.com/CC/venv/lib64/python3.9/site-packages/sqlalchemy/dialects/mysql/mysqlconnector.py", line 67, in create_default_cursor
    return self._dbapi_connection.cursor(buffered=True)
  File "/www/wwwroot/coinceeper.com/CC/venv/lib64/python3.9/site-packages/sqlalchemy/pool/base.py", line 1486, in cursor
    return self.dbapi_connection.cursor(*args, **kwargs)
  File "/www/wwwroot/coinceeper.com/CC/venv/lib64/python3.9/site-packages/mysql/connector/connection_cext.py", line 841, in cursor
    raise OperationalError("MySQL Connection not available.")
sqlalchemy.exc.OperationalError: (mysql.connector.errors.OperationalError) MySQL Connection not available.
[SQL: SELECT currencies.`CurrencyID` AS `currencies_CurrencyID`, currencies.`CurrencyName` AS `currencies_CurrencyName`, currencies.`Icon` AS `currencies_Icon`, currencies.`Symbol` AS `currencies_Symbol`, currencies.`BlockchainID` AS `currencies_BlockchainID`, currencies.`DecimalPlaces` AS `currencies_DecimalPlaces`, currencies.`IsToken` AS `currencies_IsToken`, currencies.`SmartContractAddress` AS `currencies_SmartContractAddress`, currencies.`CreatedAt` AS `currencies_CreatedAt`, currencies.`UpdatedAt` AS `currencies_UpdatedAt`, currencies.`CMC_ID` AS `currencies_CMC_ID`, blockchains.`BlockchainName` AS `blockchains_BlockchainName` 
FROM currencies INNER JOIN blockchains ON currencies.`BlockchainID` = blockchains.`BlockchainID`]
[parameters: [{}]]
(Background on this error at: https://sqlalche.me/e/20/e3q8)
2025-07-22 08:32:26 - error_handlers - ERROR - Unexpected error: 404 Not Found: The requested URL was not found on the server. If you entered the URL manually please check your spelling and try again.
Traceback (most recent call last):
  File "/www/wwwroot/coinceeper.com/CC/venv/lib64/python3.9/site-packages/flask/app.py", line 917, in full_dispatch_request
    rv = self.dispatch_request()
  File "/www/wwwroot/coinceeper.com/CC/venv/lib64/python3.9/site-packages/flask/app.py", line 891, in dispatch_request
    self.raise_routing_exception(req)
  File "/www/wwwroot/coinceeper.com/CC/venv/lib64/python3.9/site-packages/flask/app.py", line 500, in raise_routing_exception
    raise request.routing_exception  # type: ignore[misc]
  File "/www/wwwroot/coinceeper.com/CC/venv/lib64/python3.9/site-packages/flask/ctx.py", line 362, in match_request
    result = self.url_adapter.match(return_rule=True)  # type: ignore
  File "/www/wwwroot/coinceeper.com/CC/venv/lib64/python3.9/site-packages/werkzeug/routing/map.py", line 629, in match
    raise NotFound() from None
werkzeug.exceptions.NotFound: 404 Not Found: The requested URL was not found on the server. If you entered the URL manually please check your spelling and try again.
2025-07-22 08:32:26 - error_handlers - ERROR - Error traceback: Traceback (most recent call last):
  File "/www/wwwroot/coinceeper.com/CC/venv/lib64/python3.9/site-packages/flask/app.py", line 917, in full_dispatch_request
    rv = self.dispatch_request()
  File "/www/wwwroot/coinceeper.com/CC/venv/lib64/python3.9/site-packages/flask/app.py", line 891, in dispatch_request
    self.raise_routing_exception(req)
  File "/www/wwwroot/coinceeper.com/CC/venv/lib64/python3.9/site-packages/flask/app.py", line 500, in raise_routing_exception
    raise request.routing_exception  # type: ignore[misc]
  File "/www/wwwroot/coinceeper.com/CC/venv/lib64/python3.9/site-packages/flask/ctx.py", line 362, in match_request
    result = self.url_adapter.match(return_rule=True)  # type: ignore
  File "/www/wwwroot/coinceeper.com/CC/venv/lib64/python3.9/site-packages/werkzeug/routing/map.py", line 629, in match
    raise NotFound() from None
werkzeug.exceptions.NotFound: 404 Not Found: The requested URL was not found on the server. If you entered the URL manually please check your spelling and try again.

2025-07-22 10:15:21 - error_handlers - ERROR - Unexpected error: 404 Not Found: The requested URL was not found on the server. If you entered the URL manually please check your spelling and try again.
Traceback (most recent call last):
  File "/www/wwwroot/coinceeper.com/CC/venv/lib64/python3.9/site-packages/flask/app.py", line 917, in full_dispatch_request
    rv = self.dispatch_request()
  File "/www/wwwroot/coinceeper.com/CC/venv/lib64/python3.9/site-packages/flask/app.py", line 891, in dispatch_request
    self.raise_routing_exception(req)
  File "/www/wwwroot/coinceeper.com/CC/venv/lib64/python3.9/site-packages/flask/app.py", line 500, in raise_routing_exception
    raise request.routing_exception  # type: ignore[misc]
  File "/www/wwwroot/coinceeper.com/CC/venv/lib64/python3.9/site-packages/flask/ctx.py", line 362, in match_request
    result = self.url_adapter.match(return_rule=True)  # type: ignore
  File "/www/wwwroot/coinceeper.com/CC/venv/lib64/python3.9/site-packages/werkzeug/routing/map.py", line 629, in match
    raise NotFound() from None
werkzeug.exceptions.NotFound: 404 Not Found: The requested URL was not found on the server. If you entered the URL manually please check your spelling and try again.
2025-07-22 10:15:21 - error_handlers - ERROR - Error traceback: Traceback (most recent call last):
  File "/www/wwwroot/coinceeper.com/CC/venv/lib64/python3.9/site-packages/flask/app.py", line 917, in full_dispatch_request
    rv = self.dispatch_request()
  File "/www/wwwroot/coinceeper.com/CC/venv/lib64/python3.9/site-packages/flask/app.py", line 891, in dispatch_request
    self.raise_routing_exception(req)
  File "/www/wwwroot/coinceeper.com/CC/venv/lib64/python3.9/site-packages/flask/app.py", line 500, in raise_routing_exception
    raise request.routing_exception  # type: ignore[misc]
  File "/www/wwwroot/coinceeper.com/CC/venv/lib64/python3.9/site-packages/flask/ctx.py", line 362, in match_request
    result = self.url_adapter.match(return_rule=True)  # type: ignore
  File "/www/wwwroot/coinceeper.com/CC/venv/lib64/python3.9/site-packages/werkzeug/routing/map.py", line 629, in match
    raise NotFound() from None
werkzeug.exceptions.NotFound: 404 Not Found: The requested URL was not found on the server. If you entered the URL manually please check your spelling and try again.

2025-07-22 13:10:06 - error_handlers - ERROR - Unexpected error: 404 Not Found: The requested URL was not found on the server. If you entered the URL manually please check your spelling and try again.
Traceback (most recent call last):
  File "/www/wwwroot/coinceeper.com/CC/venv/lib64/python3.9/site-packages/flask/app.py", line 917, in full_dispatch_request
    rv = self.dispatch_request()
  File "/www/wwwroot/coinceeper.com/CC/venv/lib64/python3.9/site-packages/flask/app.py", line 891, in dispatch_request
    self.raise_routing_exception(req)
  File "/www/wwwroot/coinceeper.com/CC/venv/lib64/python3.9/site-packages/flask/app.py", line 500, in raise_routing_exception
    raise request.routing_exception  # type: ignore[misc]
  File "/www/wwwroot/coinceeper.com/CC/venv/lib64/python3.9/site-packages/flask/ctx.py", line 362, in match_request
    result = self.url_adapter.match(return_rule=True)  # type: ignore
  File "/www/wwwroot/coinceeper.com/CC/venv/lib64/python3.9/site-packages/werkzeug/routing/map.py", line 629, in match
    raise NotFound() from None
werkzeug.exceptions.NotFound: 404 Not Found: The requested URL was not found on the server. If you entered the URL manually please check your spelling and try again.
2025-07-22 13:10:06 - error_handlers - ERROR - Error traceback: Traceback (most recent call last):
  File "/www/wwwroot/coinceeper.com/CC/venv/lib64/python3.9/site-packages/flask/app.py", line 917, in full_dispatch_request
    rv = self.dispatch_request()
  File "/www/wwwroot/coinceeper.com/CC/venv/lib64/python3.9/site-packages/flask/app.py", line 891, in dispatch_request
    self.raise_routing_exception(req)
  File "/www/wwwroot/coinceeper.com/CC/venv/lib64/python3.9/site-packages/flask/app.py", line 500, in raise_routing_exception
    raise request.routing_exception  # type: ignore[misc]
  File "/www/wwwroot/coinceeper.com/CC/venv/lib64/python3.9/site-packages/flask/ctx.py", line 362, in match_request
    result = self.url_adapter.match(return_rule=True)  # type: ignore
  File "/www/wwwroot/coinceeper.com/CC/venv/lib64/python3.9/site-packages/werkzeug/routing/map.py", line 629, in match
    raise NotFound() from None
werkzeug.exceptions.NotFound: 404 Not Found: The requested URL was not found on the server. If you entered the URL manually please check your spelling and try again.

2025-07-22 13:10:07 - error_handlers - ERROR - Unexpected error: 404 Not Found: The requested URL was not found on the server. If you entered the URL manually please check your spelling and try again.
Traceback (most recent call last):
  File "/www/wwwroot/coinceeper.com/CC/venv/lib64/python3.9/site-packages/flask/app.py", line 917, in full_dispatch_request
    rv = self.dispatch_request()
  File "/www/wwwroot/coinceeper.com/CC/venv/lib64/python3.9/site-packages/flask/app.py", line 891, in dispatch_request
    self.raise_routing_exception(req)
  File "/www/wwwroot/coinceeper.com/CC/venv/lib64/python3.9/site-packages/flask/app.py", line 500, in raise_routing_exception
    raise request.routing_exception  # type: ignore[misc]
  File "/www/wwwroot/coinceeper.com/CC/venv/lib64/python3.9/site-packages/flask/ctx.py", line 362, in match_request
    result = self.url_adapter.match(return_rule=True)  # type: ignore
  File "/www/wwwroot/coinceeper.com/CC/venv/lib64/python3.9/site-packages/werkzeug/routing/map.py", line 629, in match
    raise NotFound() from None
werkzeug.exceptions.NotFound: 404 Not Found: The requested URL was not found on the server. If you entered the URL manually please check your spelling and try again.
2025-07-22 13:10:07 - error_handlers - ERROR - Error traceback: Traceback (most recent call last):
  File "/www/wwwroot/coinceeper.com/CC/venv/lib64/python3.9/site-packages/flask/app.py", line 917, in full_dispatch_request
    rv = self.dispatch_request()
  File "/www/wwwroot/coinceeper.com/CC/venv/lib64/python3.9/site-packages/flask/app.py", line 891, in dispatch_request
    self.raise_routing_exception(req)
  File "/www/wwwroot/coinceeper.com/CC/venv/lib64/python3.9/site-packages/flask/app.py", line 500, in raise_routing_exception
    raise request.routing_exception  # type: ignore[misc]
  File "/www/wwwroot/coinceeper.com/CC/venv/lib64/python3.9/site-packages/flask/ctx.py", line 362, in match_request
    result = self.url_adapter.match(return_rule=True)  # type: ignore
  File "/www/wwwroot/coinceeper.com/CC/venv/lib64/python3.9/site-packages/werkzeug/routing/map.py", line 629, in match
    raise NotFound() from None
werkzeug.exceptions.NotFound: 404 Not Found: The requested URL was not found on the server. If you entered the URL manually please check your spelling and try again.

2025-07-22 13:54:34 - error_handlers - ERROR - Unexpected error: 404 Not Found: The requested URL was not found on the server. If you entered the URL manually please check your spelling and try again.
Traceback (most recent call last):
  File "/www/wwwroot/coinceeper.com/CC/venv/lib64/python3.9/site-packages/flask/app.py", line 917, in full_dispatch_request
    rv = self.dispatch_request()
  File "/www/wwwroot/coinceeper.com/CC/venv/lib64/python3.9/site-packages/flask/app.py", line 891, in dispatch_request
    self.raise_routing_exception(req)
  File "/www/wwwroot/coinceeper.com/CC/venv/lib64/python3.9/site-packages/flask/app.py", line 500, in raise_routing_exception
    raise request.routing_exception  # type: ignore[misc]
  File "/www/wwwroot/coinceeper.com/CC/venv/lib64/python3.9/site-packages/flask/ctx.py", line 362, in match_request
    result = self.url_adapter.match(return_rule=True)  # type: ignore
  File "/www/wwwroot/coinceeper.com/CC/venv/lib64/python3.9/site-packages/werkzeug/routing/map.py", line 629, in match
    raise NotFound() from None
werkzeug.exceptions.NotFound: 404 Not Found: The requested URL was not found on the server. If you entered the URL manually please check your spelling and try again.
2025-07-22 13:54:34 - error_handlers - ERROR - Error traceback: Traceback (most recent call last):
  File "/www/wwwroot/coinceeper.com/CC/venv/lib64/python3.9/site-packages/flask/app.py", line 917, in full_dispatch_request
    rv = self.dispatch_request()
  File "/www/wwwroot/coinceeper.com/CC/venv/lib64/python3.9/site-packages/flask/app.py", line 891, in dispatch_request
    self.raise_routing_exception(req)
  File "/www/wwwroot/coinceeper.com/CC/venv/lib64/python3.9/site-packages/flask/app.py", line 500, in raise_routing_exception
    raise request.routing_exception  # type: ignore[misc]
  File "/www/wwwroot/coinceeper.com/CC/venv/lib64/python3.9/site-packages/flask/ctx.py", line 362, in match_request
    result = self.url_adapter.match(return_rule=True)  # type: ignore
  File "/www/wwwroot/coinceeper.com/CC/venv/lib64/python3.9/site-packages/werkzeug/routing/map.py", line 629, in match
    raise NotFound() from None
werkzeug.exceptions.NotFound: 404 Not Found: The requested URL was not found on the server. If you entered the URL manually please check your spelling and try again.

2025-07-22 14:39:07 - error_handlers - ERROR - Unexpected error: 404 Not Found: The requested URL was not found on the server. If you entered the URL manually please check your spelling and try again.
Traceback (most recent call last):
  File "/www/wwwroot/coinceeper.com/CC/venv/lib64/python3.9/site-packages/flask/app.py", line 917, in full_dispatch_request
    rv = self.dispatch_request()
  File "/www/wwwroot/coinceeper.com/CC/venv/lib64/python3.9/site-packages/flask/app.py", line 891, in dispatch_request
    self.raise_routing_exception(req)
  File "/www/wwwroot/coinceeper.com/CC/venv/lib64/python3.9/site-packages/flask/app.py", line 500, in raise_routing_exception
    raise request.routing_exception  # type: ignore[misc]
  File "/www/wwwroot/coinceeper.com/CC/venv/lib64/python3.9/site-packages/flask/ctx.py", line 362, in match_request
    result = self.url_adapter.match(return_rule=True)  # type: ignore
  File "/www/wwwroot/coinceeper.com/CC/venv/lib64/python3.9/site-packages/werkzeug/routing/map.py", line 629, in match
    raise NotFound() from None
werkzeug.exceptions.NotFound: 404 Not Found: The requested URL was not found on the server. If you entered the URL manually please check your spelling and try again.
2025-07-22 14:39:07 - error_handlers - ERROR - Error traceback: Traceback (most recent call last):
  File "/www/wwwroot/coinceeper.com/CC/venv/lib64/python3.9/site-packages/flask/app.py", line 917, in full_dispatch_request
    rv = self.dispatch_request()
  File "/www/wwwroot/coinceeper.com/CC/venv/lib64/python3.9/site-packages/flask/app.py", line 891, in dispatch_request
    self.raise_routing_exception(req)
  File "/www/wwwroot/coinceeper.com/CC/venv/lib64/python3.9/site-packages/flask/app.py", line 500, in raise_routing_exception
    raise request.routing_exception  # type: ignore[misc]
  File "/www/wwwroot/coinceeper.com/CC/venv/lib64/python3.9/site-packages/flask/ctx.py", line 362, in match_request
    result = self.url_adapter.match(return_rule=True)  # type: ignore
  File "/www/wwwroot/coinceeper.com/CC/venv/lib64/python3.9/site-packages/werkzeug/routing/map.py", line 629, in match
    raise NotFound() from None
werkzeug.exceptions.NotFound: 404 Not Found: The requested URL was not found on the server. If you entered the URL manually please check your spelling and try again.

2025-07-22 15:25:54 - error_handlers - ERROR - Unexpected error: 404 Not Found: The requested URL was not found on the server. If you entered the URL manually please check your spelling and try again.
Traceback (most recent call last):
  File "/www/wwwroot/coinceeper.com/CC/venv/lib64/python3.9/site-packages/flask/app.py", line 917, in full_dispatch_request
    rv = self.dispatch_request()
  File "/www/wwwroot/coinceeper.com/CC/venv/lib64/python3.9/site-packages/flask/app.py", line 891, in dispatch_request
    self.raise_routing_exception(req)
  File "/www/wwwroot/coinceeper.com/CC/venv/lib64/python3.9/site-packages/flask/app.py", line 500, in raise_routing_exception
    raise request.routing_exception  # type: ignore[misc]
  File "/www/wwwroot/coinceeper.com/CC/venv/lib64/python3.9/site-packages/flask/ctx.py", line 362, in match_request
    result = self.url_adapter.match(return_rule=True)  # type: ignore
  File "/www/wwwroot/coinceeper.com/CC/venv/lib64/python3.9/site-packages/werkzeug/routing/map.py", line 629, in match
    raise NotFound() from None
werkzeug.exceptions.NotFound: 404 Not Found: The requested URL was not found on the server. If you entered the URL manually please check your spelling and try again.
2025-07-22 15:25:54 - error_handlers - ERROR - Error traceback: Traceback (most recent call last):
  File "/www/wwwroot/coinceeper.com/CC/venv/lib64/python3.9/site-packages/flask/app.py", line 917, in full_dispatch_request
    rv = self.dispatch_request()
  File "/www/wwwroot/coinceeper.com/CC/venv/lib64/python3.9/site-packages/flask/app.py", line 891, in dispatch_request
    self.raise_routing_exception(req)
  File "/www/wwwroot/coinceeper.com/CC/venv/lib64/python3.9/site-packages/flask/app.py", line 500, in raise_routing_exception
    raise request.routing_exception  # type: ignore[misc]
  File "/www/wwwroot/coinceeper.com/CC/venv/lib64/python3.9/site-packages/flask/ctx.py", line 362, in match_request
    result = self.url_adapter.match(return_rule=True)  # type: ignore
  File "/www/wwwroot/coinceeper.com/CC/venv/lib64/python3.9/site-packages/werkzeug/routing/map.py", line 629, in match
    raise NotFound() from None
werkzeug.exceptions.NotFound: 404 Not Found: The requested URL was not found on the server. If you entered the URL manually please check your spelling and try again.

2025-07-22 16:00:32 - error_handlers - ERROR - Unexpected error: 404 Not Found: The requested URL was not found on the server. If you entered the URL manually please check your spelling and try again.
Traceback (most recent call last):
  File "/www/wwwroot/coinceeper.com/CC/venv/lib64/python3.9/site-packages/flask/app.py", line 917, in full_dispatch_request
    rv = self.dispatch_request()
  File "/www/wwwroot/coinceeper.com/CC/venv/lib64/python3.9/site-packages/flask/app.py", line 891, in dispatch_request
    self.raise_routing_exception(req)
  File "/www/wwwroot/coinceeper.com/CC/venv/lib64/python3.9/site-packages/flask/app.py", line 500, in raise_routing_exception
    raise request.routing_exception  # type: ignore[misc]
  File "/www/wwwroot/coinceeper.com/CC/venv/lib64/python3.9/site-packages/flask/ctx.py", line 362, in match_request
    result = self.url_adapter.match(return_rule=True)  # type: ignore
  File "/www/wwwroot/coinceeper.com/CC/venv/lib64/python3.9/site-packages/werkzeug/routing/map.py", line 629, in match
    raise NotFound() from None
werkzeug.exceptions.NotFound: 404 Not Found: The requested URL was not found on the server. If you entered the URL manually please check your spelling and try again.
2025-07-22 16:00:32 - error_handlers - ERROR - Error traceback: Traceback (most recent call last):
  File "/www/wwwroot/coinceeper.com/CC/venv/lib64/python3.9/site-packages/flask/app.py", line 917, in full_dispatch_request
    rv = self.dispatch_request()
  File "/www/wwwroot/coinceeper.com/CC/venv/lib64/python3.9/site-packages/flask/app.py", line 891, in dispatch_request
    self.raise_routing_exception(req)
  File "/www/wwwroot/coinceeper.com/CC/venv/lib64/python3.9/site-packages/flask/app.py", line 500, in raise_routing_exception
    raise request.routing_exception  # type: ignore[misc]
  File "/www/wwwroot/coinceeper.com/CC/venv/lib64/python3.9/site-packages/flask/ctx.py", line 362, in match_request
    result = self.url_adapter.match(return_rule=True)  # type: ignore
  File "/www/wwwroot/coinceeper.com/CC/venv/lib64/python3.9/site-packages/werkzeug/routing/map.py", line 629, in match
    raise NotFound() from None
werkzeug.exceptions.NotFound: 404 Not Found: The requested URL was not found on the server. If you entered the URL manually please check your spelling and try again.

2025-07-22 16:19:56 - error_handlers - ERROR - Unexpected error: 404 Not Found: The requested URL was not found on the server. If you entered the URL manually please check your spelling and try again.
Traceback (most recent call last):
  File "/www/wwwroot/coinceeper.com/CC/venv/lib64/python3.9/site-packages/flask/app.py", line 917, in full_dispatch_request
    rv = self.dispatch_request()
  File "/www/wwwroot/coinceeper.com/CC/venv/lib64/python3.9/site-packages/flask/app.py", line 891, in dispatch_request
    self.raise_routing_exception(req)
  File "/www/wwwroot/coinceeper.com/CC/venv/lib64/python3.9/site-packages/flask/app.py", line 500, in raise_routing_exception
    raise request.routing_exception  # type: ignore[misc]
  File "/www/wwwroot/coinceeper.com/CC/venv/lib64/python3.9/site-packages/flask/ctx.py", line 362, in match_request
    result = self.url_adapter.match(return_rule=True)  # type: ignore
  File "/www/wwwroot/coinceeper.com/CC/venv/lib64/python3.9/site-packages/werkzeug/routing/map.py", line 629, in match
    raise NotFound() from None
werkzeug.exceptions.NotFound: 404 Not Found: The requested URL was not found on the server. If you entered the URL manually please check your spelling and try again.
2025-07-22 16:19:56 - error_handlers - ERROR - Error traceback: Traceback (most recent call last):
  File "/www/wwwroot/coinceeper.com/CC/venv/lib64/python3.9/site-packages/flask/app.py", line 917, in full_dispatch_request
    rv = self.dispatch_request()
  File "/www/wwwroot/coinceeper.com/CC/venv/lib64/python3.9/site-packages/flask/app.py", line 891, in dispatch_request
    self.raise_routing_exception(req)
  File "/www/wwwroot/coinceeper.com/CC/venv/lib64/python3.9/site-packages/flask/app.py", line 500, in raise_routing_exception
    raise request.routing_exception  # type: ignore[misc]
  File "/www/wwwroot/coinceeper.com/CC/venv/lib64/python3.9/site-packages/flask/ctx.py", line 362, in match_request
    result = self.url_adapter.match(return_rule=True)  # type: ignore
  File "/www/wwwroot/coinceeper.com/CC/venv/lib64/python3.9/site-packages/werkzeug/routing/map.py", line 629, in match
    raise NotFound() from None
werkzeug.exceptions.NotFound: 404 Not Found: The requested URL was not found on the server. If you entered the URL manually please check your spelling and try again.

2025-07-22 16:20:00 - error_handlers - ERROR - Unexpected error: 404 Not Found: The requested URL was not found on the server. If you entered the URL manually please check your spelling and try again.
Traceback (most recent call last):
  File "/www/wwwroot/coinceeper.com/CC/venv/lib64/python3.9/site-packages/flask/app.py", line 917, in full_dispatch_request
    rv = self.dispatch_request()
  File "/www/wwwroot/coinceeper.com/CC/venv/lib64/python3.9/site-packages/flask/app.py", line 891, in dispatch_request
    self.raise_routing_exception(req)
  File "/www/wwwroot/coinceeper.com/CC/venv/lib64/python3.9/site-packages/flask/app.py", line 500, in raise_routing_exception
    raise request.routing_exception  # type: ignore[misc]
  File "/www/wwwroot/coinceeper.com/CC/venv/lib64/python3.9/site-packages/flask/ctx.py", line 362, in match_request
    result = self.url_adapter.match(return_rule=True)  # type: ignore
  File "/www/wwwroot/coinceeper.com/CC/venv/lib64/python3.9/site-packages/werkzeug/routing/map.py", line 629, in match
    raise NotFound() from None
werkzeug.exceptions.NotFound: 404 Not Found: The requested URL was not found on the server. If you entered the URL manually please check your spelling and try again.
2025-07-22 16:20:00 - error_handlers - ERROR - Error traceback: Traceback (most recent call last):
  File "/www/wwwroot/coinceeper.com/CC/venv/lib64/python3.9/site-packages/flask/app.py", line 917, in full_dispatch_request
    rv = self.dispatch_request()
  File "/www/wwwroot/coinceeper.com/CC/venv/lib64/python3.9/site-packages/flask/app.py", line 891, in dispatch_request
    self.raise_routing_exception(req)
  File "/www/wwwroot/coinceeper.com/CC/venv/lib64/python3.9/site-packages/flask/app.py", line 500, in raise_routing_exception
    raise request.routing_exception  # type: ignore[misc]
  File "/www/wwwroot/coinceeper.com/CC/venv/lib64/python3.9/site-packages/flask/ctx.py", line 362, in match_request
    result = self.url_adapter.match(return_rule=True)  # type: ignore
  File "/www/wwwroot/coinceeper.com/CC/venv/lib64/python3.9/site-packages/werkzeug/routing/map.py", line 629, in match
    raise NotFound() from None
werkzeug.exceptions.NotFound: 404 Not Found: The requested URL was not found on the server. If you entered the URL manually please check your spelling and try again.

2025-07-22 16:23:23 - error_handlers - ERROR - Unexpected error: 404 Not Found: The requested URL was not found on the server. If you entered the URL manually please check your spelling and try again.
Traceback (most recent call last):
  File "/www/wwwroot/coinceeper.com/CC/venv/lib64/python3.9/site-packages/flask/app.py", line 917, in full_dispatch_request
    rv = self.dispatch_request()
  File "/www/wwwroot/coinceeper.com/CC/venv/lib64/python3.9/site-packages/flask/app.py", line 891, in dispatch_request
    self.raise_routing_exception(req)
  File "/www/wwwroot/coinceeper.com/CC/venv/lib64/python3.9/site-packages/flask/app.py", line 500, in raise_routing_exception
    raise request.routing_exception  # type: ignore[misc]
  File "/www/wwwroot/coinceeper.com/CC/venv/lib64/python3.9/site-packages/flask/ctx.py", line 362, in match_request
    result = self.url_adapter.match(return_rule=True)  # type: ignore
  File "/www/wwwroot/coinceeper.com/CC/venv/lib64/python3.9/site-packages/werkzeug/routing/map.py", line 629, in match
    raise NotFound() from None
werkzeug.exceptions.NotFound: 404 Not Found: The requested URL was not found on the server. If you entered the URL manually please check your spelling and try again.
2025-07-22 16:23:23 - error_handlers - ERROR - Error traceback: Traceback (most recent call last):
  File "/www/wwwroot/coinceeper.com/CC/venv/lib64/python3.9/site-packages/flask/app.py", line 917, in full_dispatch_request
    rv = self.dispatch_request()
  File "/www/wwwroot/coinceeper.com/CC/venv/lib64/python3.9/site-packages/flask/app.py", line 891, in dispatch_request
    self.raise_routing_exception(req)
  File "/www/wwwroot/coinceeper.com/CC/venv/lib64/python3.9/site-packages/flask/app.py", line 500, in raise_routing_exception
    raise request.routing_exception  # type: ignore[misc]
  File "/www/wwwroot/coinceeper.com/CC/venv/lib64/python3.9/site-packages/flask/ctx.py", line 362, in match_request
    result = self.url_adapter.match(return_rule=True)  # type: ignore
  File "/www/wwwroot/coinceeper.com/CC/venv/lib64/python3.9/site-packages/werkzeug/routing/map.py", line 629, in match
    raise NotFound() from None
werkzeug.exceptions.NotFound: 404 Not Found: The requested URL was not found on the server. If you entered the URL manually please check your spelling and try again.

2025-07-22 16:24:25 - error_handlers - ERROR - Error in get_all_currencies: (mysql.connector.errors.DatabaseError) 2003 (HY000): Can't connect to MySQL server on 'localhost:3306' (111)
(Background on this error at: https://sqlalche.me/e/20/4xp6)
Traceback (most recent call last):
  File "/www/wwwroot/coinceeper.com/CC/venv/lib64/python3.9/site-packages/mysql/connector/connection_cext.py", line 354, in _open_connection
    self._cmysql.connect(**cnx_kwargs)
_mysql_connector.MySQLInterfaceError: Can't connect to MySQL server on 'localhost:3306' (111)

The above exception was the direct cause of the following exception:

Traceback (most recent call last):
  File "/www/wwwroot/coinceeper.com/CC/venv/lib64/python3.9/site-packages/sqlalchemy/engine/base.py", line 145, in __init__
    self._dbapi_connection = engine.raw_connection()
  File "/www/wwwroot/coinceeper.com/CC/venv/lib64/python3.9/site-packages/sqlalchemy/engine/base.py", line 3297, in raw_connection
    return self.pool.connect()
  File "/www/wwwroot/coinceeper.com/CC/venv/lib64/python3.9/site-packages/sqlalchemy/pool/base.py", line 449, in connect
    return _ConnectionFairy._checkout(self)
  File "/www/wwwroot/coinceeper.com/CC/venv/lib64/python3.9/site-packages/sqlalchemy/pool/base.py", line 1264, in _checkout
    fairy = _ConnectionRecord.checkout(pool)
  File "/www/wwwroot/coinceeper.com/CC/venv/lib64/python3.9/site-packages/sqlalchemy/pool/base.py", line 719, in checkout
    rec._checkin_failed(err, _fairy_was_created=False)
  File "/www/wwwroot/coinceeper.com/CC/venv/lib64/python3.9/site-packages/sqlalchemy/util/langhelpers.py", line 224, in __exit__
    raise exc_value.with_traceback(exc_tb)
  File "/www/wwwroot/coinceeper.com/CC/venv/lib64/python3.9/site-packages/sqlalchemy/pool/base.py", line 716, in checkout
    dbapi_connection = rec.get_connection()
  File "/www/wwwroot/coinceeper.com/CC/venv/lib64/python3.9/site-packages/sqlalchemy/pool/base.py", line 867, in get_connection
    self.__connect()
  File "/www/wwwroot/coinceeper.com/CC/venv/lib64/python3.9/site-packages/sqlalchemy/pool/base.py", line 902, in __connect
    pool.logger.debug("Error on connect(): %s", e)
  File "/www/wwwroot/coinceeper.com/CC/venv/lib64/python3.9/site-packages/sqlalchemy/util/langhelpers.py", line 224, in __exit__
    raise exc_value.with_traceback(exc_tb)
  File "/www/wwwroot/coinceeper.com/CC/venv/lib64/python3.9/site-packages/sqlalchemy/pool/base.py", line 897, in __connect
    self.dbapi_connection = connection = pool._invoke_creator(self)
  File "/www/wwwroot/coinceeper.com/CC/venv/lib64/python3.9/site-packages/sqlalchemy/engine/create.py", line 646, in connect
    return dialect.connect(*cargs, **cparams)
  File "/www/wwwroot/coinceeper.com/CC/venv/lib64/python3.9/site-packages/sqlalchemy/engine/default.py", line 625, in connect
    return self.loaded_dbapi.connect(*cargs, **cparams)  # type: ignore[no-any-return]  # NOQA: E501
  File "/www/wwwroot/coinceeper.com/CC/venv/lib64/python3.9/site-packages/mysql/connector/pooling.py", line 322, in connect
    return CMySQLConnection(*args, **kwargs)
  File "/www/wwwroot/coinceeper.com/CC/venv/lib64/python3.9/site-packages/mysql/connector/connection_cext.py", line 142, in __init__
    self.connect(**kwargs)
  File "/www/wwwroot/coinceeper.com/CC/venv/lib64/python3.9/site-packages/mysql/connector/abstracts.py", line 1605, in connect
    self._open_connection()
  File "/www/wwwroot/coinceeper.com/CC/venv/lib64/python3.9/site-packages/mysql/connector/connection_cext.py", line 360, in _open_connection
    raise get_mysql_exception(
mysql.connector.errors.DatabaseError: 2003 (HY000): Can't connect to MySQL server on 'localhost:3306' (111)

The above exception was the direct cause of the following exception:

Traceback (most recent call last):
  File "/www/wwwroot/coinceeper.com/CC/utils/error_handlers.py", line 119, in decorated_function
    return f(*args, **kwargs)
  File "/www/wwwroot/coinceeper.com/CC/Currencies/All_Currencies.py", line 46, in get_all_currencies
    currencies_query = session.query(
  File "/www/wwwroot/coinceeper.com/CC/venv/lib64/python3.9/site-packages/sqlalchemy/orm/query.py", line 2704, in all
    return self._iter().all()  # type: ignore
  File "/www/wwwroot/coinceeper.com/CC/venv/lib64/python3.9/site-packages/sqlalchemy/orm/query.py", line 2857, in _iter
    result: Union[ScalarResult[_T], Result[_T]] = self.session.execute(
  File "/www/wwwroot/coinceeper.com/CC/venv/lib64/python3.9/site-packages/sqlalchemy/orm/session.py", line 2365, in execute
    return self._execute_internal(
  File "/www/wwwroot/coinceeper.com/CC/venv/lib64/python3.9/site-packages/sqlalchemy/orm/session.py", line 2241, in _execute_internal
    conn = self._connection_for_bind(bind)
  File "/www/wwwroot/coinceeper.com/CC/venv/lib64/python3.9/site-packages/sqlalchemy/orm/session.py", line 2110, in _connection_for_bind
    return trans._connection_for_bind(engine, execution_options)
  File "<string>", line 2, in _connection_for_bind
  File "/www/wwwroot/coinceeper.com/CC/venv/lib64/python3.9/site-packages/sqlalchemy/orm/state_changes.py", line 139, in _go
    ret_value = fn(self, *arg, **kw)
  File "/www/wwwroot/coinceeper.com/CC/venv/lib64/python3.9/site-packages/sqlalchemy/orm/session.py", line 1189, in _connection_for_bind
    conn = bind.connect()
  File "/www/wwwroot/coinceeper.com/CC/venv/lib64/python3.9/site-packages/sqlalchemy/engine/base.py", line 3273, in connect
    return self._connection_cls(self)
  File "/www/wwwroot/coinceeper.com/CC/venv/lib64/python3.9/site-packages/sqlalchemy/engine/base.py", line 147, in __init__
    Connection._handle_dbapi_exception_noconnection(
  File "/www/wwwroot/coinceeper.com/CC/venv/lib64/python3.9/site-packages/sqlalchemy/engine/base.py", line 2436, in _handle_dbapi_exception_noconnection
    raise sqlalchemy_exception.with_traceback(exc_info[2]) from e
  File "/www/wwwroot/coinceeper.com/CC/venv/lib64/python3.9/site-packages/sqlalchemy/engine/base.py", line 145, in __init__
    self._dbapi_connection = engine.raw_connection()
  File "/www/wwwroot/coinceeper.com/CC/venv/lib64/python3.9/site-packages/sqlalchemy/engine/base.py", line 3297, in raw_connection
    return self.pool.connect()
  File "/www/wwwroot/coinceeper.com/CC/venv/lib64/python3.9/site-packages/sqlalchemy/pool/base.py", line 449, in connect
    return _ConnectionFairy._checkout(self)
  File "/www/wwwroot/coinceeper.com/CC/venv/lib64/python3.9/site-packages/sqlalchemy/pool/base.py", line 1264, in _checkout
    fairy = _ConnectionRecord.checkout(pool)
  File "/www/wwwroot/coinceeper.com/CC/venv/lib64/python3.9/site-packages/sqlalchemy/pool/base.py", line 719, in checkout
    rec._checkin_failed(err, _fairy_was_created=False)
  File "/www/wwwroot/coinceeper.com/CC/venv/lib64/python3.9/site-packages/sqlalchemy/util/langhelpers.py", line 224, in __exit__
    raise exc_value.with_traceback(exc_tb)
  File "/www/wwwroot/coinceeper.com/CC/venv/lib64/python3.9/site-packages/sqlalchemy/pool/base.py", line 716, in checkout
    dbapi_connection = rec.get_connection()
  File "/www/wwwroot/coinceeper.com/CC/venv/lib64/python3.9/site-packages/sqlalchemy/pool/base.py", line 867, in get_connection
    self.__connect()
  File "/www/wwwroot/coinceeper.com/CC/venv/lib64/python3.9/site-packages/sqlalchemy/pool/base.py", line 902, in __connect
    pool.logger.debug("Error on connect(): %s", e)
  File "/www/wwwroot/coinceeper.com/CC/venv/lib64/python3.9/site-packages/sqlalchemy/util/langhelpers.py", line 224, in __exit__
    raise exc_value.with_traceback(exc_tb)
  File "/www/wwwroot/coinceeper.com/CC/venv/lib64/python3.9/site-packages/sqlalchemy/pool/base.py", line 897, in __connect
    self.dbapi_connection = connection = pool._invoke_creator(self)
  File "/www/wwwroot/coinceeper.com/CC/venv/lib64/python3.9/site-packages/sqlalchemy/engine/create.py", line 646, in connect
    return dialect.connect(*cargs, **cparams)
  File "/www/wwwroot/coinceeper.com/CC/venv/lib64/python3.9/site-packages/sqlalchemy/engine/default.py", line 625, in connect
    return self.loaded_dbapi.connect(*cargs, **cparams)  # type: ignore[no-any-return]  # NOQA: E501
  File "/www/wwwroot/coinceeper.com/CC/venv/lib64/python3.9/site-packages/mysql/connector/pooling.py", line 322, in connect
    return CMySQLConnection(*args, **kwargs)
  File "/www/wwwroot/coinceeper.com/CC/venv/lib64/python3.9/site-packages/mysql/connector/connection_cext.py", line 142, in __init__
    self.connect(**kwargs)
  File "/www/wwwroot/coinceeper.com/CC/venv/lib64/python3.9/site-packages/mysql/connector/abstracts.py", line 1605, in connect
    self._open_connection()
  File "/www/wwwroot/coinceeper.com/CC/venv/lib64/python3.9/site-packages/mysql/connector/connection_cext.py", line 360, in _open_connection
    raise get_mysql_exception(
sqlalchemy.exc.DatabaseError: (mysql.connector.errors.DatabaseError) 2003 (HY000): Can't connect to MySQL server on 'localhost:3306' (111)
(Background on this error at: https://sqlalche.me/e/20/4xp6)
2025-07-22 16:24:25 - error_handlers - ERROR - Database error: (mysql.connector.errors.DatabaseError) 2003 (HY000): Can't connect to MySQL server on 'localhost:3306' (111)
(Background on this error at: https://sqlalche.me/e/20/4xp6)
Traceback (most recent call last):
  File "/www/wwwroot/coinceeper.com/CC/venv/lib64/python3.9/site-packages/mysql/connector/connection_cext.py", line 354, in _open_connection
    self._cmysql.connect(**cnx_kwargs)
_mysql_connector.MySQLInterfaceError: Can't connect to MySQL server on 'localhost:3306' (111)

The above exception was the direct cause of the following exception:

Traceback (most recent call last):
  File "/www/wwwroot/coinceeper.com/CC/venv/lib64/python3.9/site-packages/sqlalchemy/engine/base.py", line 145, in __init__
    self._dbapi_connection = engine.raw_connection()
  File "/www/wwwroot/coinceeper.com/CC/venv/lib64/python3.9/site-packages/sqlalchemy/engine/base.py", line 3297, in raw_connection
    return self.pool.connect()
  File "/www/wwwroot/coinceeper.com/CC/venv/lib64/python3.9/site-packages/sqlalchemy/pool/base.py", line 449, in connect
    return _ConnectionFairy._checkout(self)
  File "/www/wwwroot/coinceeper.com/CC/venv/lib64/python3.9/site-packages/sqlalchemy/pool/base.py", line 1264, in _checkout
    fairy = _ConnectionRecord.checkout(pool)
  File "/www/wwwroot/coinceeper.com/CC/venv/lib64/python3.9/site-packages/sqlalchemy/pool/base.py", line 719, in checkout
    rec._checkin_failed(err, _fairy_was_created=False)
  File "/www/wwwroot/coinceeper.com/CC/venv/lib64/python3.9/site-packages/sqlalchemy/util/langhelpers.py", line 224, in __exit__
    raise exc_value.with_traceback(exc_tb)
  File "/www/wwwroot/coinceeper.com/CC/venv/lib64/python3.9/site-packages/sqlalchemy/pool/base.py", line 716, in checkout
    dbapi_connection = rec.get_connection()
  File "/www/wwwroot/coinceeper.com/CC/venv/lib64/python3.9/site-packages/sqlalchemy/pool/base.py", line 867, in get_connection
    self.__connect()
  File "/www/wwwroot/coinceeper.com/CC/venv/lib64/python3.9/site-packages/sqlalchemy/pool/base.py", line 902, in __connect
    pool.logger.debug("Error on connect(): %s", e)
  File "/www/wwwroot/coinceeper.com/CC/venv/lib64/python3.9/site-packages/sqlalchemy/util/langhelpers.py", line 224, in __exit__
    raise exc_value.with_traceback(exc_tb)
  File "/www/wwwroot/coinceeper.com/CC/venv/lib64/python3.9/site-packages/sqlalchemy/pool/base.py", line 897, in __connect
    self.dbapi_connection = connection = pool._invoke_creator(self)
  File "/www/wwwroot/coinceeper.com/CC/venv/lib64/python3.9/site-packages/sqlalchemy/engine/create.py", line 646, in connect
    return dialect.connect(*cargs, **cparams)
  File "/www/wwwroot/coinceeper.com/CC/venv/lib64/python3.9/site-packages/sqlalchemy/engine/default.py", line 625, in connect
    return self.loaded_dbapi.connect(*cargs, **cparams)  # type: ignore[no-any-return]  # NOQA: E501
  File "/www/wwwroot/coinceeper.com/CC/venv/lib64/python3.9/site-packages/mysql/connector/pooling.py", line 322, in connect
    return CMySQLConnection(*args, **kwargs)
  File "/www/wwwroot/coinceeper.com/CC/venv/lib64/python3.9/site-packages/mysql/connector/connection_cext.py", line 142, in __init__
    self.connect(**kwargs)
  File "/www/wwwroot/coinceeper.com/CC/venv/lib64/python3.9/site-packages/mysql/connector/abstracts.py", line 1605, in connect
    self._open_connection()
  File "/www/wwwroot/coinceeper.com/CC/venv/lib64/python3.9/site-packages/mysql/connector/connection_cext.py", line 360, in _open_connection
    raise get_mysql_exception(
mysql.connector.errors.DatabaseError: 2003 (HY000): Can't connect to MySQL server on 'localhost:3306' (111)

The above exception was the direct cause of the following exception:

Traceback (most recent call last):
  File "/www/wwwroot/coinceeper.com/CC/utils/error_handlers.py", line 119, in decorated_function
    return f(*args, **kwargs)
  File "/www/wwwroot/coinceeper.com/CC/Currencies/All_Currencies.py", line 46, in get_all_currencies
    currencies_query = session.query(
  File "/www/wwwroot/coinceeper.com/CC/venv/lib64/python3.9/site-packages/sqlalchemy/orm/query.py", line 2704, in all
    return self._iter().all()  # type: ignore
  File "/www/wwwroot/coinceeper.com/CC/venv/lib64/python3.9/site-packages/sqlalchemy/orm/query.py", line 2857, in _iter
    result: Union[ScalarResult[_T], Result[_T]] = self.session.execute(
  File "/www/wwwroot/coinceeper.com/CC/venv/lib64/python3.9/site-packages/sqlalchemy/orm/session.py", line 2365, in execute
    return self._execute_internal(
  File "/www/wwwroot/coinceeper.com/CC/venv/lib64/python3.9/site-packages/sqlalchemy/orm/session.py", line 2241, in _execute_internal
    conn = self._connection_for_bind(bind)
  File "/www/wwwroot/coinceeper.com/CC/venv/lib64/python3.9/site-packages/sqlalchemy/orm/session.py", line 2110, in _connection_for_bind
    return trans._connection_for_bind(engine, execution_options)
  File "<string>", line 2, in _connection_for_bind
  File "/www/wwwroot/coinceeper.com/CC/venv/lib64/python3.9/site-packages/sqlalchemy/orm/state_changes.py", line 139, in _go
    ret_value = fn(self, *arg, **kw)
  File "/www/wwwroot/coinceeper.com/CC/venv/lib64/python3.9/site-packages/sqlalchemy/orm/session.py", line 1189, in _connection_for_bind
    conn = bind.connect()
  File "/www/wwwroot/coinceeper.com/CC/venv/lib64/python3.9/site-packages/sqlalchemy/engine/base.py", line 3273, in connect
    return self._connection_cls(self)
  File "/www/wwwroot/coinceeper.com/CC/venv/lib64/python3.9/site-packages/sqlalchemy/engine/base.py", line 147, in __init__
    Connection._handle_dbapi_exception_noconnection(
  File "/www/wwwroot/coinceeper.com/CC/venv/lib64/python3.9/site-packages/sqlalchemy/engine/base.py", line 2436, in _handle_dbapi_exception_noconnection
    raise sqlalchemy_exception.with_traceback(exc_info[2]) from e
  File "/www/wwwroot/coinceeper.com/CC/venv/lib64/python3.9/site-packages/sqlalchemy/engine/base.py", line 145, in __init__
    self._dbapi_connection = engine.raw_connection()
  File "/www/wwwroot/coinceeper.com/CC/venv/lib64/python3.9/site-packages/sqlalchemy/engine/base.py", line 3297, in raw_connection
    return self.pool.connect()
  File "/www/wwwroot/coinceeper.com/CC/venv/lib64/python3.9/site-packages/sqlalchemy/pool/base.py", line 449, in connect
    return _ConnectionFairy._checkout(self)
  File "/www/wwwroot/coinceeper.com/CC/venv/lib64/python3.9/site-packages/sqlalchemy/pool/base.py", line 1264, in _checkout
    fairy = _ConnectionRecord.checkout(pool)
  File "/www/wwwroot/coinceeper.com/CC/venv/lib64/python3.9/site-packages/sqlalchemy/pool/base.py", line 719, in checkout
    rec._checkin_failed(err, _fairy_was_created=False)
  File "/www/wwwroot/coinceeper.com/CC/venv/lib64/python3.9/site-packages/sqlalchemy/util/langhelpers.py", line 224, in __exit__
    raise exc_value.with_traceback(exc_tb)
  File "/www/wwwroot/coinceeper.com/CC/venv/lib64/python3.9/site-packages/sqlalchemy/pool/base.py", line 716, in checkout
    dbapi_connection = rec.get_connection()
  File "/www/wwwroot/coinceeper.com/CC/venv/lib64/python3.9/site-packages/sqlalchemy/pool/base.py", line 867, in get_connection
    self.__connect()
  File "/www/wwwroot/coinceeper.com/CC/venv/lib64/python3.9/site-packages/sqlalchemy/pool/base.py", line 902, in __connect
    pool.logger.debug("Error on connect(): %s", e)
  File "/www/wwwroot/coinceeper.com/CC/venv/lib64/python3.9/site-packages/sqlalchemy/util/langhelpers.py", line 224, in __exit__
    raise exc_value.with_traceback(exc_tb)
  File "/www/wwwroot/coinceeper.com/CC/venv/lib64/python3.9/site-packages/sqlalchemy/pool/base.py", line 897, in __connect
    self.dbapi_connection = connection = pool._invoke_creator(self)
  File "/www/wwwroot/coinceeper.com/CC/venv/lib64/python3.9/site-packages/sqlalchemy/engine/create.py", line 646, in connect
    return dialect.connect(*cargs, **cparams)
  File "/www/wwwroot/coinceeper.com/CC/venv/lib64/python3.9/site-packages/sqlalchemy/engine/default.py", line 625, in connect
    return self.loaded_dbapi.connect(*cargs, **cparams)  # type: ignore[no-any-return]  # NOQA: E501
  File "/www/wwwroot/coinceeper.com/CC/venv/lib64/python3.9/site-packages/mysql/connector/pooling.py", line 322, in connect
    return CMySQLConnection(*args, **kwargs)
  File "/www/wwwroot/coinceeper.com/CC/venv/lib64/python3.9/site-packages/mysql/connector/connection_cext.py", line 142, in __init__
    self.connect(**kwargs)
  File "/www/wwwroot/coinceeper.com/CC/venv/lib64/python3.9/site-packages/mysql/connector/abstracts.py", line 1605, in connect
    self._open_connection()
  File "/www/wwwroot/coinceeper.com/CC/venv/lib64/python3.9/site-packages/mysql/connector/connection_cext.py", line 360, in _open_connection
    raise get_mysql_exception(
sqlalchemy.exc.DatabaseError: (mysql.connector.errors.DatabaseError) 2003 (HY000): Can't connect to MySQL server on 'localhost:3306' (111)
(Background on this error at: https://sqlalche.me/e/20/4xp6)
2025-07-22 16:42:18 - error_handlers - ERROR - Unexpected error: 404 Not Found: The requested URL was not found on the server. If you entered the URL manually please check your spelling and try again.
Traceback (most recent call last):
  File "/www/wwwroot/coinceeper.com/CC/venv/lib64/python3.9/site-packages/flask/app.py", line 917, in full_dispatch_request
    rv = self.dispatch_request()
  File "/www/wwwroot/coinceeper.com/CC/venv/lib64/python3.9/site-packages/flask/app.py", line 891, in dispatch_request
    self.raise_routing_exception(req)
  File "/www/wwwroot/coinceeper.com/CC/venv/lib64/python3.9/site-packages/flask/app.py", line 500, in raise_routing_exception
    raise request.routing_exception  # type: ignore[misc]
  File "/www/wwwroot/coinceeper.com/CC/venv/lib64/python3.9/site-packages/flask/ctx.py", line 362, in match_request
    result = self.url_adapter.match(return_rule=True)  # type: ignore
  File "/www/wwwroot/coinceeper.com/CC/venv/lib64/python3.9/site-packages/werkzeug/routing/map.py", line 629, in match
    raise NotFound() from None
werkzeug.exceptions.NotFound: 404 Not Found: The requested URL was not found on the server. If you entered the URL manually please check your spelling and try again.
2025-07-22 16:42:18 - error_handlers - ERROR - Error traceback: Traceback (most recent call last):
  File "/www/wwwroot/coinceeper.com/CC/venv/lib64/python3.9/site-packages/flask/app.py", line 917, in full_dispatch_request
    rv = self.dispatch_request()
  File "/www/wwwroot/coinceeper.com/CC/venv/lib64/python3.9/site-packages/flask/app.py", line 891, in dispatch_request
    self.raise_routing_exception(req)
  File "/www/wwwroot/coinceeper.com/CC/venv/lib64/python3.9/site-packages/flask/app.py", line 500, in raise_routing_exception
    raise request.routing_exception  # type: ignore[misc]
  File "/www/wwwroot/coinceeper.com/CC/venv/lib64/python3.9/site-packages/flask/ctx.py", line 362, in match_request
    result = self.url_adapter.match(return_rule=True)  # type: ignore
  File "/www/wwwroot/coinceeper.com/CC/venv/lib64/python3.9/site-packages/werkzeug/routing/map.py", line 629, in match
    raise NotFound() from None
werkzeug.exceptions.NotFound: 404 Not Found: The requested URL was not found on the server. If you entered the URL manually please check your spelling and try again.

2025-07-22 17:18:10 - error_handlers - DEBUG - Logger initialized for error_handlers at level DEBUG
2025-07-22 17:18:10 - error_handlers - INFO - Initializing error handling module
2025-07-22 17:18:10 - error_handlers - DEBUG - Logger initialized for error_handlers at level DEBUG
2025-07-22 17:18:10 - error_handlers - INFO - Initializing error handling module
2025-07-22 17:18:10 - error_handlers - DEBUG - Logger initialized for error_handlers at level DEBUG
2025-07-22 17:18:10 - error_handlers - INFO - Initializing error handling module
2025-07-22 17:18:17 - error_handlers - INFO - Initializing error handling module
2025-07-22 17:18:17 - error_handlers - INFO - Initializing error handling module
2025-07-22 17:18:17 - error_handlers - INFO - Initializing error handling module
2025-07-22 17:31:01 - error_handlers - ERROR - Unexpected error: 405 Method Not Allowed: The method is not allowed for the requested URL.
Traceback (most recent call last):
  File "/www/wwwroot/coinceeper.com/CC/venv/lib64/python3.9/site-packages/flask/app.py", line 917, in full_dispatch_request
    rv = self.dispatch_request()
  File "/www/wwwroot/coinceeper.com/CC/venv/lib64/python3.9/site-packages/flask/app.py", line 891, in dispatch_request
    self.raise_routing_exception(req)
  File "/www/wwwroot/coinceeper.com/CC/venv/lib64/python3.9/site-packages/flask/app.py", line 500, in raise_routing_exception
    raise request.routing_exception  # type: ignore[misc]
  File "/www/wwwroot/coinceeper.com/CC/venv/lib64/python3.9/site-packages/flask/ctx.py", line 362, in match_request
    result = self.url_adapter.match(return_rule=True)  # type: ignore
  File "/www/wwwroot/coinceeper.com/CC/venv/lib64/python3.9/site-packages/werkzeug/routing/map.py", line 624, in match
    raise MethodNotAllowed(valid_methods=list(e.have_match_for)) from None
werkzeug.exceptions.MethodNotAllowed: 405 Method Not Allowed: The method is not allowed for the requested URL.
2025-07-22 17:31:01 - error_handlers - ERROR - Error traceback: Traceback (most recent call last):
  File "/www/wwwroot/coinceeper.com/CC/venv/lib64/python3.9/site-packages/flask/app.py", line 917, in full_dispatch_request
    rv = self.dispatch_request()
  File "/www/wwwroot/coinceeper.com/CC/venv/lib64/python3.9/site-packages/flask/app.py", line 891, in dispatch_request
    self.raise_routing_exception(req)
  File "/www/wwwroot/coinceeper.com/CC/venv/lib64/python3.9/site-packages/flask/app.py", line 500, in raise_routing_exception
    raise request.routing_exception  # type: ignore[misc]
  File "/www/wwwroot/coinceeper.com/CC/venv/lib64/python3.9/site-packages/flask/ctx.py", line 362, in match_request
    result = self.url_adapter.match(return_rule=True)  # type: ignore
  File "/www/wwwroot/coinceeper.com/CC/venv/lib64/python3.9/site-packages/werkzeug/routing/map.py", line 624, in match
    raise MethodNotAllowed(valid_methods=list(e.have_match_for)) from None
werkzeug.exceptions.MethodNotAllowed: 405 Method Not Allowed: The method is not allowed for the requested URL.

2025-07-22 17:33:52 - error_handlers - DEBUG - Logger initialized for error_handlers at level DEBUG
2025-07-22 17:33:52 - error_handlers - INFO - Initializing error handling module
2025-07-22 17:33:52 - error_handlers - DEBUG - Logger initialized for error_handlers at level DEBUG
2025-07-22 17:33:52 - error_handlers - INFO - Initializing error handling module
2025-07-22 17:33:52 - error_handlers - DEBUG - Logger initialized for error_handlers at level DEBUG
2025-07-22 17:33:52 - error_handlers - INFO - Initializing error handling module
2025-07-22 17:33:59 - error_handlers - INFO - Initializing error handling module
2025-07-22 17:33:59 - error_handlers - INFO - Initializing error handling module
2025-07-22 17:33:59 - error_handlers - INFO - Initializing error handling module
2025-07-22 18:08:18 - error_handlers - ERROR - Unexpected error: 404 Not Found: The requested URL was not found on the server. If you entered the URL manually please check your spelling and try again.
Traceback (most recent call last):
  File "/www/wwwroot/coinceeper.com/CC/venv/lib64/python3.9/site-packages/flask/app.py", line 917, in full_dispatch_request
    rv = self.dispatch_request()
  File "/www/wwwroot/coinceeper.com/CC/venv/lib64/python3.9/site-packages/flask/app.py", line 891, in dispatch_request
    self.raise_routing_exception(req)
  File "/www/wwwroot/coinceeper.com/CC/venv/lib64/python3.9/site-packages/flask/app.py", line 500, in raise_routing_exception
    raise request.routing_exception  # type: ignore[misc]
  File "/www/wwwroot/coinceeper.com/CC/venv/lib64/python3.9/site-packages/flask/ctx.py", line 362, in match_request
    result = self.url_adapter.match(return_rule=True)  # type: ignore
  File "/www/wwwroot/coinceeper.com/CC/venv/lib64/python3.9/site-packages/werkzeug/routing/map.py", line 629, in match
    raise NotFound() from None
werkzeug.exceptions.NotFound: 404 Not Found: The requested URL was not found on the server. If you entered the URL manually please check your spelling and try again.
2025-07-22 18:08:18 - error_handlers - ERROR - Error traceback: Traceback (most recent call last):
  File "/www/wwwroot/coinceeper.com/CC/venv/lib64/python3.9/site-packages/flask/app.py", line 917, in full_dispatch_request
    rv = self.dispatch_request()
  File "/www/wwwroot/coinceeper.com/CC/venv/lib64/python3.9/site-packages/flask/app.py", line 891, in dispatch_request
    self.raise_routing_exception(req)
  File "/www/wwwroot/coinceeper.com/CC/venv/lib64/python3.9/site-packages/flask/app.py", line 500, in raise_routing_exception
    raise request.routing_exception  # type: ignore[misc]
  File "/www/wwwroot/coinceeper.com/CC/venv/lib64/python3.9/site-packages/flask/ctx.py", line 362, in match_request
    result = self.url_adapter.match(return_rule=True)  # type: ignore
  File "/www/wwwroot/coinceeper.com/CC/venv/lib64/python3.9/site-packages/werkzeug/routing/map.py", line 629, in match
    raise NotFound() from None
werkzeug.exceptions.NotFound: 404 Not Found: The requested URL was not found on the server. If you entered the URL manually please check your spelling and try again.

2025-07-22 18:10:19 - error_handlers - ERROR - Unexpected error: 404 Not Found: The requested URL was not found on the server. If you entered the URL manually please check your spelling and try again.
Traceback (most recent call last):
  File "/www/wwwroot/coinceeper.com/CC/venv/lib64/python3.9/site-packages/flask/app.py", line 917, in full_dispatch_request
    rv = self.dispatch_request()
  File "/www/wwwroot/coinceeper.com/CC/venv/lib64/python3.9/site-packages/flask/app.py", line 891, in dispatch_request
    self.raise_routing_exception(req)
  File "/www/wwwroot/coinceeper.com/CC/venv/lib64/python3.9/site-packages/flask/app.py", line 500, in raise_routing_exception
    raise request.routing_exception  # type: ignore[misc]
  File "/www/wwwroot/coinceeper.com/CC/venv/lib64/python3.9/site-packages/flask/ctx.py", line 362, in match_request
    result = self.url_adapter.match(return_rule=True)  # type: ignore
  File "/www/wwwroot/coinceeper.com/CC/venv/lib64/python3.9/site-packages/werkzeug/routing/map.py", line 629, in match
    raise NotFound() from None
werkzeug.exceptions.NotFound: 404 Not Found: The requested URL was not found on the server. If you entered the URL manually please check your spelling and try again.
2025-07-22 18:10:19 - error_handlers - ERROR - Error traceback: Traceback (most recent call last):
  File "/www/wwwroot/coinceeper.com/CC/venv/lib64/python3.9/site-packages/flask/app.py", line 917, in full_dispatch_request
    rv = self.dispatch_request()
  File "/www/wwwroot/coinceeper.com/CC/venv/lib64/python3.9/site-packages/flask/app.py", line 891, in dispatch_request
    self.raise_routing_exception(req)
  File "/www/wwwroot/coinceeper.com/CC/venv/lib64/python3.9/site-packages/flask/app.py", line 500, in raise_routing_exception
    raise request.routing_exception  # type: ignore[misc]
  File "/www/wwwroot/coinceeper.com/CC/venv/lib64/python3.9/site-packages/flask/ctx.py", line 362, in match_request
    result = self.url_adapter.match(return_rule=True)  # type: ignore
  File "/www/wwwroot/coinceeper.com/CC/venv/lib64/python3.9/site-packages/werkzeug/routing/map.py", line 629, in match
    raise NotFound() from None
werkzeug.exceptions.NotFound: 404 Not Found: The requested URL was not found on the server. If you entered the URL manually please check your spelling and try again.

2025-07-22 18:33:01 - error_handlers - ERROR - Unexpected error: 404 Not Found: The requested URL was not found on the server. If you entered the URL manually please check your spelling and try again.
Traceback (most recent call last):
  File "/www/wwwroot/coinceeper.com/CC/venv/lib64/python3.9/site-packages/flask/app.py", line 917, in full_dispatch_request
    rv = self.dispatch_request()
  File "/www/wwwroot/coinceeper.com/CC/venv/lib64/python3.9/site-packages/flask/app.py", line 891, in dispatch_request
    self.raise_routing_exception(req)
  File "/www/wwwroot/coinceeper.com/CC/venv/lib64/python3.9/site-packages/flask/app.py", line 500, in raise_routing_exception
    raise request.routing_exception  # type: ignore[misc]
  File "/www/wwwroot/coinceeper.com/CC/venv/lib64/python3.9/site-packages/flask/ctx.py", line 362, in match_request
    result = self.url_adapter.match(return_rule=True)  # type: ignore
  File "/www/wwwroot/coinceeper.com/CC/venv/lib64/python3.9/site-packages/werkzeug/routing/map.py", line 629, in match
    raise NotFound() from None
werkzeug.exceptions.NotFound: 404 Not Found: The requested URL was not found on the server. If you entered the URL manually please check your spelling and try again.
2025-07-22 18:33:01 - error_handlers - ERROR - Error traceback: Traceback (most recent call last):
  File "/www/wwwroot/coinceeper.com/CC/venv/lib64/python3.9/site-packages/flask/app.py", line 917, in full_dispatch_request
    rv = self.dispatch_request()
  File "/www/wwwroot/coinceeper.com/CC/venv/lib64/python3.9/site-packages/flask/app.py", line 891, in dispatch_request
    self.raise_routing_exception(req)
  File "/www/wwwroot/coinceeper.com/CC/venv/lib64/python3.9/site-packages/flask/app.py", line 500, in raise_routing_exception
    raise request.routing_exception  # type: ignore[misc]
  File "/www/wwwroot/coinceeper.com/CC/venv/lib64/python3.9/site-packages/flask/ctx.py", line 362, in match_request
    result = self.url_adapter.match(return_rule=True)  # type: ignore
  File "/www/wwwroot/coinceeper.com/CC/venv/lib64/python3.9/site-packages/werkzeug/routing/map.py", line 629, in match
    raise NotFound() from None
werkzeug.exceptions.NotFound: 404 Not Found: The requested URL was not found on the server. If you entered the URL manually please check your spelling and try again.

2025-07-22 18:46:44 - error_handlers - ERROR - Unexpected error: 404 Not Found: The requested URL was not found on the server. If you entered the URL manually please check your spelling and try again.
Traceback (most recent call last):
  File "/www/wwwroot/coinceeper.com/CC/venv/lib64/python3.9/site-packages/flask/app.py", line 917, in full_dispatch_request
    rv = self.dispatch_request()
  File "/www/wwwroot/coinceeper.com/CC/venv/lib64/python3.9/site-packages/flask/app.py", line 891, in dispatch_request
    self.raise_routing_exception(req)
  File "/www/wwwroot/coinceeper.com/CC/venv/lib64/python3.9/site-packages/flask/app.py", line 500, in raise_routing_exception
    raise request.routing_exception  # type: ignore[misc]
  File "/www/wwwroot/coinceeper.com/CC/venv/lib64/python3.9/site-packages/flask/ctx.py", line 362, in match_request
    result = self.url_adapter.match(return_rule=True)  # type: ignore
  File "/www/wwwroot/coinceeper.com/CC/venv/lib64/python3.9/site-packages/werkzeug/routing/map.py", line 629, in match
    raise NotFound() from None
werkzeug.exceptions.NotFound: 404 Not Found: The requested URL was not found on the server. If you entered the URL manually please check your spelling and try again.
2025-07-22 18:46:44 - error_handlers - ERROR - Error traceback: Traceback (most recent call last):
  File "/www/wwwroot/coinceeper.com/CC/venv/lib64/python3.9/site-packages/flask/app.py", line 917, in full_dispatch_request
    rv = self.dispatch_request()
  File "/www/wwwroot/coinceeper.com/CC/venv/lib64/python3.9/site-packages/flask/app.py", line 891, in dispatch_request
    self.raise_routing_exception(req)
  File "/www/wwwroot/coinceeper.com/CC/venv/lib64/python3.9/site-packages/flask/app.py", line 500, in raise_routing_exception
    raise request.routing_exception  # type: ignore[misc]
  File "/www/wwwroot/coinceeper.com/CC/venv/lib64/python3.9/site-packages/flask/ctx.py", line 362, in match_request
    result = self.url_adapter.match(return_rule=True)  # type: ignore
  File "/www/wwwroot/coinceeper.com/CC/venv/lib64/python3.9/site-packages/werkzeug/routing/map.py", line 629, in match
    raise NotFound() from None
werkzeug.exceptions.NotFound: 404 Not Found: The requested URL was not found on the server. If you entered the URL manually please check your spelling and try again.

2025-07-22 19:12:27 - error_handlers - ERROR - Unexpected error: 404 Not Found: The requested URL was not found on the server. If you entered the URL manually please check your spelling and try again.
Traceback (most recent call last):
  File "/www/wwwroot/coinceeper.com/CC/venv/lib64/python3.9/site-packages/flask/app.py", line 917, in full_dispatch_request
    rv = self.dispatch_request()
  File "/www/wwwroot/coinceeper.com/CC/venv/lib64/python3.9/site-packages/flask/app.py", line 891, in dispatch_request
    self.raise_routing_exception(req)
  File "/www/wwwroot/coinceeper.com/CC/venv/lib64/python3.9/site-packages/flask/app.py", line 500, in raise_routing_exception
    raise request.routing_exception  # type: ignore[misc]
  File "/www/wwwroot/coinceeper.com/CC/venv/lib64/python3.9/site-packages/flask/ctx.py", line 362, in match_request
    result = self.url_adapter.match(return_rule=True)  # type: ignore
  File "/www/wwwroot/coinceeper.com/CC/venv/lib64/python3.9/site-packages/werkzeug/routing/map.py", line 629, in match
    raise NotFound() from None
werkzeug.exceptions.NotFound: 404 Not Found: The requested URL was not found on the server. If you entered the URL manually please check your spelling and try again.
2025-07-22 19:12:27 - error_handlers - ERROR - Error traceback: Traceback (most recent call last):
  File "/www/wwwroot/coinceeper.com/CC/venv/lib64/python3.9/site-packages/flask/app.py", line 917, in full_dispatch_request
    rv = self.dispatch_request()
  File "/www/wwwroot/coinceeper.com/CC/venv/lib64/python3.9/site-packages/flask/app.py", line 891, in dispatch_request
    self.raise_routing_exception(req)
  File "/www/wwwroot/coinceeper.com/CC/venv/lib64/python3.9/site-packages/flask/app.py", line 500, in raise_routing_exception
    raise request.routing_exception  # type: ignore[misc]
  File "/www/wwwroot/coinceeper.com/CC/venv/lib64/python3.9/site-packages/flask/ctx.py", line 362, in match_request
    result = self.url_adapter.match(return_rule=True)  # type: ignore
  File "/www/wwwroot/coinceeper.com/CC/venv/lib64/python3.9/site-packages/werkzeug/routing/map.py", line 629, in match
    raise NotFound() from None
werkzeug.exceptions.NotFound: 404 Not Found: The requested URL was not found on the server. If you entered the URL manually please check your spelling and try again.

2025-07-22 19:12:29 - error_handlers - ERROR - Unexpected error: 404 Not Found: The requested URL was not found on the server. If you entered the URL manually please check your spelling and try again.
Traceback (most recent call last):
  File "/www/wwwroot/coinceeper.com/CC/venv/lib64/python3.9/site-packages/flask/app.py", line 917, in full_dispatch_request
    rv = self.dispatch_request()
  File "/www/wwwroot/coinceeper.com/CC/venv/lib64/python3.9/site-packages/flask/app.py", line 891, in dispatch_request
    self.raise_routing_exception(req)
  File "/www/wwwroot/coinceeper.com/CC/venv/lib64/python3.9/site-packages/flask/app.py", line 500, in raise_routing_exception
    raise request.routing_exception  # type: ignore[misc]
  File "/www/wwwroot/coinceeper.com/CC/venv/lib64/python3.9/site-packages/flask/ctx.py", line 362, in match_request
    result = self.url_adapter.match(return_rule=True)  # type: ignore
  File "/www/wwwroot/coinceeper.com/CC/venv/lib64/python3.9/site-packages/werkzeug/routing/map.py", line 629, in match
    raise NotFound() from None
werkzeug.exceptions.NotFound: 404 Not Found: The requested URL was not found on the server. If you entered the URL manually please check your spelling and try again.
2025-07-22 19:12:29 - error_handlers - ERROR - Error traceback: Traceback (most recent call last):
  File "/www/wwwroot/coinceeper.com/CC/venv/lib64/python3.9/site-packages/flask/app.py", line 917, in full_dispatch_request
    rv = self.dispatch_request()
  File "/www/wwwroot/coinceeper.com/CC/venv/lib64/python3.9/site-packages/flask/app.py", line 891, in dispatch_request
    self.raise_routing_exception(req)
  File "/www/wwwroot/coinceeper.com/CC/venv/lib64/python3.9/site-packages/flask/app.py", line 500, in raise_routing_exception
    raise request.routing_exception  # type: ignore[misc]
  File "/www/wwwroot/coinceeper.com/CC/venv/lib64/python3.9/site-packages/flask/ctx.py", line 362, in match_request
    result = self.url_adapter.match(return_rule=True)  # type: ignore
  File "/www/wwwroot/coinceeper.com/CC/venv/lib64/python3.9/site-packages/werkzeug/routing/map.py", line 629, in match
    raise NotFound() from None
werkzeug.exceptions.NotFound: 404 Not Found: The requested URL was not found on the server. If you entered the URL manually please check your spelling and try again.

2025-07-22 19:26:35 - error_handlers - ERROR - Unexpected error: 404 Not Found: The requested URL was not found on the server. If you entered the URL manually please check your spelling and try again.
Traceback (most recent call last):
  File "/www/wwwroot/coinceeper.com/CC/venv/lib64/python3.9/site-packages/flask/app.py", line 917, in full_dispatch_request
    rv = self.dispatch_request()
  File "/www/wwwroot/coinceeper.com/CC/venv/lib64/python3.9/site-packages/flask/app.py", line 891, in dispatch_request
    self.raise_routing_exception(req)
  File "/www/wwwroot/coinceeper.com/CC/venv/lib64/python3.9/site-packages/flask/app.py", line 500, in raise_routing_exception
    raise request.routing_exception  # type: ignore[misc]
  File "/www/wwwroot/coinceeper.com/CC/venv/lib64/python3.9/site-packages/flask/ctx.py", line 362, in match_request
    result = self.url_adapter.match(return_rule=True)  # type: ignore
  File "/www/wwwroot/coinceeper.com/CC/venv/lib64/python3.9/site-packages/werkzeug/routing/map.py", line 629, in match
    raise NotFound() from None
werkzeug.exceptions.NotFound: 404 Not Found: The requested URL was not found on the server. If you entered the URL manually please check your spelling and try again.
2025-07-22 19:26:35 - error_handlers - ERROR - Error traceback: Traceback (most recent call last):
  File "/www/wwwroot/coinceeper.com/CC/venv/lib64/python3.9/site-packages/flask/app.py", line 917, in full_dispatch_request
    rv = self.dispatch_request()
  File "/www/wwwroot/coinceeper.com/CC/venv/lib64/python3.9/site-packages/flask/app.py", line 891, in dispatch_request
    self.raise_routing_exception(req)
  File "/www/wwwroot/coinceeper.com/CC/venv/lib64/python3.9/site-packages/flask/app.py", line 500, in raise_routing_exception
    raise request.routing_exception  # type: ignore[misc]
  File "/www/wwwroot/coinceeper.com/CC/venv/lib64/python3.9/site-packages/flask/ctx.py", line 362, in match_request
    result = self.url_adapter.match(return_rule=True)  # type: ignore
  File "/www/wwwroot/coinceeper.com/CC/venv/lib64/python3.9/site-packages/werkzeug/routing/map.py", line 629, in match
    raise NotFound() from None
werkzeug.exceptions.NotFound: 404 Not Found: The requested URL was not found on the server. If you entered the URL manually please check your spelling and try again.

2025-07-22 19:26:36 - error_handlers - ERROR - Unexpected error: 405 Method Not Allowed: The method is not allowed for the requested URL.
Traceback (most recent call last):
  File "/www/wwwroot/coinceeper.com/CC/venv/lib64/python3.9/site-packages/flask/app.py", line 917, in full_dispatch_request
    rv = self.dispatch_request()
  File "/www/wwwroot/coinceeper.com/CC/venv/lib64/python3.9/site-packages/flask/app.py", line 891, in dispatch_request
    self.raise_routing_exception(req)
  File "/www/wwwroot/coinceeper.com/CC/venv/lib64/python3.9/site-packages/flask/app.py", line 500, in raise_routing_exception
    raise request.routing_exception  # type: ignore[misc]
  File "/www/wwwroot/coinceeper.com/CC/venv/lib64/python3.9/site-packages/flask/ctx.py", line 362, in match_request
    result = self.url_adapter.match(return_rule=True)  # type: ignore
  File "/www/wwwroot/coinceeper.com/CC/venv/lib64/python3.9/site-packages/werkzeug/routing/map.py", line 624, in match
    raise MethodNotAllowed(valid_methods=list(e.have_match_for)) from None
werkzeug.exceptions.MethodNotAllowed: 405 Method Not Allowed: The method is not allowed for the requested URL.
2025-07-22 19:26:36 - error_handlers - ERROR - Error traceback: Traceback (most recent call last):
  File "/www/wwwroot/coinceeper.com/CC/venv/lib64/python3.9/site-packages/flask/app.py", line 917, in full_dispatch_request
    rv = self.dispatch_request()
  File "/www/wwwroot/coinceeper.com/CC/venv/lib64/python3.9/site-packages/flask/app.py", line 891, in dispatch_request
    self.raise_routing_exception(req)
  File "/www/wwwroot/coinceeper.com/CC/venv/lib64/python3.9/site-packages/flask/app.py", line 500, in raise_routing_exception
    raise request.routing_exception  # type: ignore[misc]
  File "/www/wwwroot/coinceeper.com/CC/venv/lib64/python3.9/site-packages/flask/ctx.py", line 362, in match_request
    result = self.url_adapter.match(return_rule=True)  # type: ignore
  File "/www/wwwroot/coinceeper.com/CC/venv/lib64/python3.9/site-packages/werkzeug/routing/map.py", line 624, in match
    raise MethodNotAllowed(valid_methods=list(e.have_match_for)) from None
werkzeug.exceptions.MethodNotAllowed: 405 Method Not Allowed: The method is not allowed for the requested URL.

2025-07-22 20:18:46 - error_handlers - ERROR - Unexpected error: 404 Not Found: The requested URL was not found on the server. If you entered the URL manually please check your spelling and try again.
Traceback (most recent call last):
  File "/www/wwwroot/coinceeper.com/CC/venv/lib64/python3.9/site-packages/flask/app.py", line 917, in full_dispatch_request
    rv = self.dispatch_request()
  File "/www/wwwroot/coinceeper.com/CC/venv/lib64/python3.9/site-packages/flask/app.py", line 891, in dispatch_request
    self.raise_routing_exception(req)
  File "/www/wwwroot/coinceeper.com/CC/venv/lib64/python3.9/site-packages/flask/app.py", line 500, in raise_routing_exception
    raise request.routing_exception  # type: ignore[misc]
  File "/www/wwwroot/coinceeper.com/CC/venv/lib64/python3.9/site-packages/flask/ctx.py", line 362, in match_request
    result = self.url_adapter.match(return_rule=True)  # type: ignore
  File "/www/wwwroot/coinceeper.com/CC/venv/lib64/python3.9/site-packages/werkzeug/routing/map.py", line 629, in match
    raise NotFound() from None
werkzeug.exceptions.NotFound: 404 Not Found: The requested URL was not found on the server. If you entered the URL manually please check your spelling and try again.
2025-07-22 20:18:46 - error_handlers - ERROR - Error traceback: Traceback (most recent call last):
  File "/www/wwwroot/coinceeper.com/CC/venv/lib64/python3.9/site-packages/flask/app.py", line 917, in full_dispatch_request
    rv = self.dispatch_request()
  File "/www/wwwroot/coinceeper.com/CC/venv/lib64/python3.9/site-packages/flask/app.py", line 891, in dispatch_request
    self.raise_routing_exception(req)
  File "/www/wwwroot/coinceeper.com/CC/venv/lib64/python3.9/site-packages/flask/app.py", line 500, in raise_routing_exception
    raise request.routing_exception  # type: ignore[misc]
  File "/www/wwwroot/coinceeper.com/CC/venv/lib64/python3.9/site-packages/flask/ctx.py", line 362, in match_request
    result = self.url_adapter.match(return_rule=True)  # type: ignore
  File "/www/wwwroot/coinceeper.com/CC/venv/lib64/python3.9/site-packages/werkzeug/routing/map.py", line 629, in match
    raise NotFound() from None
werkzeug.exceptions.NotFound: 404 Not Found: The requested URL was not found on the server. If you entered the URL manually please check your spelling and try again.

2025-07-22 20:28:14 - error_handlers - DEBUG - Logger initialized for error_handlers at level DEBUG
2025-07-22 20:28:14 - error_handlers - INFO - Initializing error handling module
2025-07-22 20:28:14 - error_handlers - DEBUG - Logger initialized for error_handlers at level DEBUG
2025-07-22 20:28:14 - error_handlers - INFO - Initializing error handling module
2025-07-22 20:28:14 - error_handlers - DEBUG - Logger initialized for error_handlers at level DEBUG
2025-07-22 20:28:14 - error_handlers - INFO - Initializing error handling module
2025-07-22 20:28:20 - error_handlers - INFO - Initializing error handling module
2025-07-22 20:28:20 - error_handlers - INFO - Initializing error handling module
2025-07-22 20:28:20 - error_handlers - INFO - Initializing error handling module
2025-07-22 20:31:19 - error_handlers - DEBUG - Logger initialized for error_handlers at level DEBUG
2025-07-22 20:31:19 - error_handlers - INFO - Initializing error handling module
2025-07-22 20:31:19 - error_handlers - DEBUG - Logger initialized for error_handlers at level DEBUG
2025-07-22 20:31:19 - error_handlers - INFO - Initializing error handling module
2025-07-22 20:31:19 - error_handlers - DEBUG - Logger initialized for error_handlers at level DEBUG
2025-07-22 20:31:19 - error_handlers - INFO - Initializing error handling module
2025-07-22 20:31:23 - error_handlers - INFO - Initializing error handling module
2025-07-22 20:31:23 - error_handlers - INFO - Initializing error handling module
2025-07-22 20:31:23 - error_handlers - INFO - Initializing error handling module
2025-07-22 20:31:57 - error_handlers - DEBUG - Logger initialized for error_handlers at level DEBUG
2025-07-22 20:31:57 - error_handlers - INFO - Initializing error handling module
2025-07-22 20:31:57 - error_handlers - DEBUG - Logger initialized for error_handlers at level DEBUG
2025-07-22 20:31:57 - error_handlers - INFO - Initializing error handling module
2025-07-22 20:31:57 - error_handlers - DEBUG - Logger initialized for error_handlers at level DEBUG
2025-07-22 20:31:57 - error_handlers - INFO - Initializing error handling module
2025-07-22 20:32:03 - error_handlers - INFO - Initializing error handling module
2025-07-22 20:32:04 - error_handlers - INFO - Initializing error handling module
2025-07-22 20:32:04 - error_handlers - INFO - Initializing error handling module
2025-07-22 20:34:08 - error_handlers - DEBUG - Logger initialized for error_handlers at level DEBUG
2025-07-22 20:34:08 - error_handlers - INFO - Initializing error handling module
2025-07-22 20:34:08 - error_handlers - DEBUG - Logger initialized for error_handlers at level DEBUG
2025-07-22 20:34:08 - error_handlers - INFO - Initializing error handling module
2025-07-22 20:34:08 - error_handlers - DEBUG - Logger initialized for error_handlers at level DEBUG
2025-07-22 20:34:08 - error_handlers - INFO - Initializing error handling module
2025-07-22 20:34:13 - error_handlers - INFO - Initializing error handling module
2025-07-22 20:34:14 - error_handlers - INFO - Initializing error handling module
2025-07-22 20:34:14 - error_handlers - INFO - Initializing error handling module
2025-07-22 20:34:22 - error_handlers - DEBUG - Logger initialized for error_handlers at level DEBUG
2025-07-22 20:34:22 - error_handlers - INFO - Initializing error handling module
2025-07-22 20:34:22 - error_handlers - DEBUG - Logger initialized for error_handlers at level DEBUG
2025-07-22 20:34:22 - error_handlers - INFO - Initializing error handling module
2025-07-22 20:34:23 - error_handlers - DEBUG - Logger initialized for error_handlers at level DEBUG
2025-07-22 20:34:23 - error_handlers - INFO - Initializing error handling module
2025-07-22 20:34:26 - error_handlers - INFO - Initializing error handling module
2025-07-22 20:34:26 - error_handlers - INFO - Initializing error handling module
2025-07-22 20:34:26 - error_handlers - INFO - Initializing error handling module
2025-07-22 20:46:39 - error_handlers - DEBUG - Logger initialized for error_handlers at level DEBUG
2025-07-22 20:46:39 - error_handlers - INFO - Initializing error handling module
2025-07-22 20:46:39 - error_handlers - DEBUG - Logger initialized for error_handlers at level DEBUG
2025-07-22 20:46:39 - error_handlers - INFO - Initializing error handling module
2025-07-22 20:46:40 - error_handlers - DEBUG - Logger initialized for error_handlers at level DEBUG
2025-07-22 20:46:40 - error_handlers - INFO - Initializing error handling module
2025-07-22 20:46:45 - error_handlers - INFO - Initializing error handling module
2025-07-22 20:46:45 - error_handlers - INFO - Initializing error handling module
2025-07-22 20:46:45 - error_handlers - INFO - Initializing error handling module
2025-07-22 21:21:17 - error_handlers - ERROR - Error in get_all_currencies: (mysql.connector.errors.DatabaseError) 2003 (HY000): Can't connect to MySQL server on 'localhost:3306' (111)
(Background on this error at: https://sqlalche.me/e/20/4xp6)
Traceback (most recent call last):
  File "/www/wwwroot/coinceeper.com/CC/venv/lib64/python3.9/site-packages/sqlalchemy/pool/base.py", line 1311, in _checkout
    raise exc.InvalidatePoolError()
sqlalchemy.exc.InvalidatePoolError: ()

During handling of the above exception, another exception occurred:

Traceback (most recent call last):
  File "/www/wwwroot/coinceeper.com/CC/venv/lib64/python3.9/site-packages/mysql/connector/connection_cext.py", line 354, in _open_connection
    self._cmysql.connect(**cnx_kwargs)
_mysql_connector.MySQLInterfaceError: Can't connect to MySQL server on 'localhost:3306' (111)

The above exception was the direct cause of the following exception:

Traceback (most recent call last):
  File "/www/wwwroot/coinceeper.com/CC/venv/lib64/python3.9/site-packages/sqlalchemy/engine/base.py", line 145, in __init__
    self._dbapi_connection = engine.raw_connection()
  File "/www/wwwroot/coinceeper.com/CC/venv/lib64/python3.9/site-packages/sqlalchemy/engine/base.py", line 3297, in raw_connection
    return self.pool.connect()
  File "/www/wwwroot/coinceeper.com/CC/venv/lib64/python3.9/site-packages/sqlalchemy/pool/base.py", line 449, in connect
    return _ConnectionFairy._checkout(self)
  File "/www/wwwroot/coinceeper.com/CC/venv/lib64/python3.9/site-packages/sqlalchemy/pool/base.py", line 1356, in _checkout
    del fairy
  File "/www/wwwroot/coinceeper.com/CC/venv/lib64/python3.9/site-packages/sqlalchemy/util/langhelpers.py", line 224, in __exit__
    raise exc_value.with_traceback(exc_tb)
  File "/www/wwwroot/coinceeper.com/CC/venv/lib64/python3.9/site-packages/sqlalchemy/pool/base.py", line 1342, in _checkout
    fairy._connection_record.get_connection()
  File "/www/wwwroot/coinceeper.com/CC/venv/lib64/python3.9/site-packages/sqlalchemy/pool/base.py", line 838, in get_connection
    self.__connect()
  File "/www/wwwroot/coinceeper.com/CC/venv/lib64/python3.9/site-packages/sqlalchemy/pool/base.py", line 902, in __connect
    pool.logger.debug("Error on connect(): %s", e)
  File "/www/wwwroot/coinceeper.com/CC/venv/lib64/python3.9/site-packages/sqlalchemy/util/langhelpers.py", line 224, in __exit__
    raise exc_value.with_traceback(exc_tb)
  File "/www/wwwroot/coinceeper.com/CC/venv/lib64/python3.9/site-packages/sqlalchemy/pool/base.py", line 897, in __connect
    self.dbapi_connection = connection = pool._invoke_creator(self)
  File "/www/wwwroot/coinceeper.com/CC/venv/lib64/python3.9/site-packages/sqlalchemy/engine/create.py", line 646, in connect
    return dialect.connect(*cargs, **cparams)
  File "/www/wwwroot/coinceeper.com/CC/venv/lib64/python3.9/site-packages/sqlalchemy/engine/default.py", line 625, in connect
    return self.loaded_dbapi.connect(*cargs, **cparams)  # type: ignore[no-any-return]  # NOQA: E501
  File "/www/wwwroot/coinceeper.com/CC/venv/lib64/python3.9/site-packages/mysql/connector/pooling.py", line 322, in connect
    return CMySQLConnection(*args, **kwargs)
  File "/www/wwwroot/coinceeper.com/CC/venv/lib64/python3.9/site-packages/mysql/connector/connection_cext.py", line 142, in __init__
    self.connect(**kwargs)
  File "/www/wwwroot/coinceeper.com/CC/venv/lib64/python3.9/site-packages/mysql/connector/abstracts.py", line 1605, in connect
    self._open_connection()
  File "/www/wwwroot/coinceeper.com/CC/venv/lib64/python3.9/site-packages/mysql/connector/connection_cext.py", line 360, in _open_connection
    raise get_mysql_exception(
mysql.connector.errors.DatabaseError: 2003 (HY000): Can't connect to MySQL server on 'localhost:3306' (111)

The above exception was the direct cause of the following exception:

Traceback (most recent call last):
  File "/www/wwwroot/coinceeper.com/CC/utils/error_handlers.py", line 119, in decorated_function
    return f(*args, **kwargs)
  File "/www/wwwroot/coinceeper.com/CC/Currencies/All_Currencies.py", line 46, in get_all_currencies
    currencies_query = session.query(
  File "/www/wwwroot/coinceeper.com/CC/venv/lib64/python3.9/site-packages/sqlalchemy/orm/query.py", line 2704, in all
    return self._iter().all()  # type: ignore
  File "/www/wwwroot/coinceeper.com/CC/venv/lib64/python3.9/site-packages/sqlalchemy/orm/query.py", line 2857, in _iter
    result: Union[ScalarResult[_T], Result[_T]] = self.session.execute(
  File "/www/wwwroot/coinceeper.com/CC/venv/lib64/python3.9/site-packages/sqlalchemy/orm/session.py", line 2365, in execute
    return self._execute_internal(
  File "/www/wwwroot/coinceeper.com/CC/venv/lib64/python3.9/site-packages/sqlalchemy/orm/session.py", line 2241, in _execute_internal
    conn = self._connection_for_bind(bind)
  File "/www/wwwroot/coinceeper.com/CC/venv/lib64/python3.9/site-packages/sqlalchemy/orm/session.py", line 2110, in _connection_for_bind
    return trans._connection_for_bind(engine, execution_options)
  File "<string>", line 2, in _connection_for_bind
  File "/www/wwwroot/coinceeper.com/CC/venv/lib64/python3.9/site-packages/sqlalchemy/orm/state_changes.py", line 139, in _go
    ret_value = fn(self, *arg, **kw)
  File "/www/wwwroot/coinceeper.com/CC/venv/lib64/python3.9/site-packages/sqlalchemy/orm/session.py", line 1189, in _connection_for_bind
    conn = bind.connect()
  File "/www/wwwroot/coinceeper.com/CC/venv/lib64/python3.9/site-packages/sqlalchemy/engine/base.py", line 3273, in connect
    return self._connection_cls(self)
  File "/www/wwwroot/coinceeper.com/CC/venv/lib64/python3.9/site-packages/sqlalchemy/engine/base.py", line 147, in __init__
    Connection._handle_dbapi_exception_noconnection(
  File "/www/wwwroot/coinceeper.com/CC/venv/lib64/python3.9/site-packages/sqlalchemy/engine/base.py", line 2436, in _handle_dbapi_exception_noconnection
    raise sqlalchemy_exception.with_traceback(exc_info[2]) from e
  File "/www/wwwroot/coinceeper.com/CC/venv/lib64/python3.9/site-packages/sqlalchemy/engine/base.py", line 145, in __init__
    self._dbapi_connection = engine.raw_connection()
  File "/www/wwwroot/coinceeper.com/CC/venv/lib64/python3.9/site-packages/sqlalchemy/engine/base.py", line 3297, in raw_connection
    return self.pool.connect()
  File "/www/wwwroot/coinceeper.com/CC/venv/lib64/python3.9/site-packages/sqlalchemy/pool/base.py", line 449, in connect
    return _ConnectionFairy._checkout(self)
  File "/www/wwwroot/coinceeper.com/CC/venv/lib64/python3.9/site-packages/sqlalchemy/pool/base.py", line 1356, in _checkout
    del fairy
  File "/www/wwwroot/coinceeper.com/CC/venv/lib64/python3.9/site-packages/sqlalchemy/util/langhelpers.py", line 224, in __exit__
    raise exc_value.with_traceback(exc_tb)
  File "/www/wwwroot/coinceeper.com/CC/venv/lib64/python3.9/site-packages/sqlalchemy/pool/base.py", line 1342, in _checkout
    fairy._connection_record.get_connection()
  File "/www/wwwroot/coinceeper.com/CC/venv/lib64/python3.9/site-packages/sqlalchemy/pool/base.py", line 838, in get_connection
    self.__connect()
  File "/www/wwwroot/coinceeper.com/CC/venv/lib64/python3.9/site-packages/sqlalchemy/pool/base.py", line 902, in __connect
    pool.logger.debug("Error on connect(): %s", e)
  File "/www/wwwroot/coinceeper.com/CC/venv/lib64/python3.9/site-packages/sqlalchemy/util/langhelpers.py", line 224, in __exit__
    raise exc_value.with_traceback(exc_tb)
  File "/www/wwwroot/coinceeper.com/CC/venv/lib64/python3.9/site-packages/sqlalchemy/pool/base.py", line 897, in __connect
    self.dbapi_connection = connection = pool._invoke_creator(self)
  File "/www/wwwroot/coinceeper.com/CC/venv/lib64/python3.9/site-packages/sqlalchemy/engine/create.py", line 646, in connect
    return dialect.connect(*cargs, **cparams)
  File "/www/wwwroot/coinceeper.com/CC/venv/lib64/python3.9/site-packages/sqlalchemy/engine/default.py", line 625, in connect
    return self.loaded_dbapi.connect(*cargs, **cparams)  # type: ignore[no-any-return]  # NOQA: E501
  File "/www/wwwroot/coinceeper.com/CC/venv/lib64/python3.9/site-packages/mysql/connector/pooling.py", line 322, in connect
    return CMySQLConnection(*args, **kwargs)
  File "/www/wwwroot/coinceeper.com/CC/venv/lib64/python3.9/site-packages/mysql/connector/connection_cext.py", line 142, in __init__
    self.connect(**kwargs)
  File "/www/wwwroot/coinceeper.com/CC/venv/lib64/python3.9/site-packages/mysql/connector/abstracts.py", line 1605, in connect
    self._open_connection()
  File "/www/wwwroot/coinceeper.com/CC/venv/lib64/python3.9/site-packages/mysql/connector/connection_cext.py", line 360, in _open_connection
    raise get_mysql_exception(
sqlalchemy.exc.DatabaseError: (mysql.connector.errors.DatabaseError) 2003 (HY000): Can't connect to MySQL server on 'localhost:3306' (111)
(Background on this error at: https://sqlalche.me/e/20/4xp6)
2025-07-22 21:21:17 - error_handlers - ERROR - Database error: (mysql.connector.errors.DatabaseError) 2003 (HY000): Can't connect to MySQL server on 'localhost:3306' (111)
(Background on this error at: https://sqlalche.me/e/20/4xp6)
Traceback (most recent call last):
  File "/www/wwwroot/coinceeper.com/CC/venv/lib64/python3.9/site-packages/sqlalchemy/pool/base.py", line 1311, in _checkout
    raise exc.InvalidatePoolError()
sqlalchemy.exc.InvalidatePoolError: ()

During handling of the above exception, another exception occurred:

Traceback (most recent call last):
  File "/www/wwwroot/coinceeper.com/CC/venv/lib64/python3.9/site-packages/mysql/connector/connection_cext.py", line 354, in _open_connection
    self._cmysql.connect(**cnx_kwargs)
_mysql_connector.MySQLInterfaceError: Can't connect to MySQL server on 'localhost:3306' (111)

The above exception was the direct cause of the following exception:

Traceback (most recent call last):
  File "/www/wwwroot/coinceeper.com/CC/venv/lib64/python3.9/site-packages/sqlalchemy/engine/base.py", line 145, in __init__
    self._dbapi_connection = engine.raw_connection()
  File "/www/wwwroot/coinceeper.com/CC/venv/lib64/python3.9/site-packages/sqlalchemy/engine/base.py", line 3297, in raw_connection
    return self.pool.connect()
  File "/www/wwwroot/coinceeper.com/CC/venv/lib64/python3.9/site-packages/sqlalchemy/pool/base.py", line 449, in connect
    return _ConnectionFairy._checkout(self)
  File "/www/wwwroot/coinceeper.com/CC/venv/lib64/python3.9/site-packages/sqlalchemy/pool/base.py", line 1356, in _checkout
    del fairy
  File "/www/wwwroot/coinceeper.com/CC/venv/lib64/python3.9/site-packages/sqlalchemy/util/langhelpers.py", line 224, in __exit__
    raise exc_value.with_traceback(exc_tb)
  File "/www/wwwroot/coinceeper.com/CC/venv/lib64/python3.9/site-packages/sqlalchemy/pool/base.py", line 1342, in _checkout
    fairy._connection_record.get_connection()
  File "/www/wwwroot/coinceeper.com/CC/venv/lib64/python3.9/site-packages/sqlalchemy/pool/base.py", line 838, in get_connection
    self.__connect()
  File "/www/wwwroot/coinceeper.com/CC/venv/lib64/python3.9/site-packages/sqlalchemy/pool/base.py", line 902, in __connect
    pool.logger.debug("Error on connect(): %s", e)
  File "/www/wwwroot/coinceeper.com/CC/venv/lib64/python3.9/site-packages/sqlalchemy/util/langhelpers.py", line 224, in __exit__
    raise exc_value.with_traceback(exc_tb)
  File "/www/wwwroot/coinceeper.com/CC/venv/lib64/python3.9/site-packages/sqlalchemy/pool/base.py", line 897, in __connect
    self.dbapi_connection = connection = pool._invoke_creator(self)
  File "/www/wwwroot/coinceeper.com/CC/venv/lib64/python3.9/site-packages/sqlalchemy/engine/create.py", line 646, in connect
    return dialect.connect(*cargs, **cparams)
  File "/www/wwwroot/coinceeper.com/CC/venv/lib64/python3.9/site-packages/sqlalchemy/engine/default.py", line 625, in connect
    return self.loaded_dbapi.connect(*cargs, **cparams)  # type: ignore[no-any-return]  # NOQA: E501
  File "/www/wwwroot/coinceeper.com/CC/venv/lib64/python3.9/site-packages/mysql/connector/pooling.py", line 322, in connect
    return CMySQLConnection(*args, **kwargs)
  File "/www/wwwroot/coinceeper.com/CC/venv/lib64/python3.9/site-packages/mysql/connector/connection_cext.py", line 142, in __init__
    self.connect(**kwargs)
  File "/www/wwwroot/coinceeper.com/CC/venv/lib64/python3.9/site-packages/mysql/connector/abstracts.py", line 1605, in connect
    self._open_connection()
  File "/www/wwwroot/coinceeper.com/CC/venv/lib64/python3.9/site-packages/mysql/connector/connection_cext.py", line 360, in _open_connection
    raise get_mysql_exception(
mysql.connector.errors.DatabaseError: 2003 (HY000): Can't connect to MySQL server on 'localhost:3306' (111)

The above exception was the direct cause of the following exception:

Traceback (most recent call last):
  File "/www/wwwroot/coinceeper.com/CC/utils/error_handlers.py", line 119, in decorated_function
    return f(*args, **kwargs)
  File "/www/wwwroot/coinceeper.com/CC/Currencies/All_Currencies.py", line 46, in get_all_currencies
    currencies_query = session.query(
  File "/www/wwwroot/coinceeper.com/CC/venv/lib64/python3.9/site-packages/sqlalchemy/orm/query.py", line 2704, in all
    return self._iter().all()  # type: ignore
  File "/www/wwwroot/coinceeper.com/CC/venv/lib64/python3.9/site-packages/sqlalchemy/orm/query.py", line 2857, in _iter
    result: Union[ScalarResult[_T], Result[_T]] = self.session.execute(
  File "/www/wwwroot/coinceeper.com/CC/venv/lib64/python3.9/site-packages/sqlalchemy/orm/session.py", line 2365, in execute
    return self._execute_internal(
  File "/www/wwwroot/coinceeper.com/CC/venv/lib64/python3.9/site-packages/sqlalchemy/orm/session.py", line 2241, in _execute_internal
    conn = self._connection_for_bind(bind)
  File "/www/wwwroot/coinceeper.com/CC/venv/lib64/python3.9/site-packages/sqlalchemy/orm/session.py", line 2110, in _connection_for_bind
    return trans._connection_for_bind(engine, execution_options)
  File "<string>", line 2, in _connection_for_bind
  File "/www/wwwroot/coinceeper.com/CC/venv/lib64/python3.9/site-packages/sqlalchemy/orm/state_changes.py", line 139, in _go
    ret_value = fn(self, *arg, **kw)
  File "/www/wwwroot/coinceeper.com/CC/venv/lib64/python3.9/site-packages/sqlalchemy/orm/session.py", line 1189, in _connection_for_bind
    conn = bind.connect()
  File "/www/wwwroot/coinceeper.com/CC/venv/lib64/python3.9/site-packages/sqlalchemy/engine/base.py", line 3273, in connect
    return self._connection_cls(self)
  File "/www/wwwroot/coinceeper.com/CC/venv/lib64/python3.9/site-packages/sqlalchemy/engine/base.py", line 147, in __init__
    Connection._handle_dbapi_exception_noconnection(
  File "/www/wwwroot/coinceeper.com/CC/venv/lib64/python3.9/site-packages/sqlalchemy/engine/base.py", line 2436, in _handle_dbapi_exception_noconnection
    raise sqlalchemy_exception.with_traceback(exc_info[2]) from e
  File "/www/wwwroot/coinceeper.com/CC/venv/lib64/python3.9/site-packages/sqlalchemy/engine/base.py", line 145, in __init__
    self._dbapi_connection = engine.raw_connection()
  File "/www/wwwroot/coinceeper.com/CC/venv/lib64/python3.9/site-packages/sqlalchemy/engine/base.py", line 3297, in raw_connection
    return self.pool.connect()
  File "/www/wwwroot/coinceeper.com/CC/venv/lib64/python3.9/site-packages/sqlalchemy/pool/base.py", line 449, in connect
    return _ConnectionFairy._checkout(self)
  File "/www/wwwroot/coinceeper.com/CC/venv/lib64/python3.9/site-packages/sqlalchemy/pool/base.py", line 1356, in _checkout
    del fairy
  File "/www/wwwroot/coinceeper.com/CC/venv/lib64/python3.9/site-packages/sqlalchemy/util/langhelpers.py", line 224, in __exit__
    raise exc_value.with_traceback(exc_tb)
  File "/www/wwwroot/coinceeper.com/CC/venv/lib64/python3.9/site-packages/sqlalchemy/pool/base.py", line 1342, in _checkout
    fairy._connection_record.get_connection()
  File "/www/wwwroot/coinceeper.com/CC/venv/lib64/python3.9/site-packages/sqlalchemy/pool/base.py", line 838, in get_connection
    self.__connect()
  File "/www/wwwroot/coinceeper.com/CC/venv/lib64/python3.9/site-packages/sqlalchemy/pool/base.py", line 902, in __connect
    pool.logger.debug("Error on connect(): %s", e)
  File "/www/wwwroot/coinceeper.com/CC/venv/lib64/python3.9/site-packages/sqlalchemy/util/langhelpers.py", line 224, in __exit__
    raise exc_value.with_traceback(exc_tb)
  File "/www/wwwroot/coinceeper.com/CC/venv/lib64/python3.9/site-packages/sqlalchemy/pool/base.py", line 897, in __connect
    self.dbapi_connection = connection = pool._invoke_creator(self)
  File "/www/wwwroot/coinceeper.com/CC/venv/lib64/python3.9/site-packages/sqlalchemy/engine/create.py", line 646, in connect
    return dialect.connect(*cargs, **cparams)
  File "/www/wwwroot/coinceeper.com/CC/venv/lib64/python3.9/site-packages/sqlalchemy/engine/default.py", line 625, in connect
    return self.loaded_dbapi.connect(*cargs, **cparams)  # type: ignore[no-any-return]  # NOQA: E501
  File "/www/wwwroot/coinceeper.com/CC/venv/lib64/python3.9/site-packages/mysql/connector/pooling.py", line 322, in connect
    return CMySQLConnection(*args, **kwargs)
  File "/www/wwwroot/coinceeper.com/CC/venv/lib64/python3.9/site-packages/mysql/connector/connection_cext.py", line 142, in __init__
    self.connect(**kwargs)
  File "/www/wwwroot/coinceeper.com/CC/venv/lib64/python3.9/site-packages/mysql/connector/abstracts.py", line 1605, in connect
    self._open_connection()
  File "/www/wwwroot/coinceeper.com/CC/venv/lib64/python3.9/site-packages/mysql/connector/connection_cext.py", line 360, in _open_connection
    raise get_mysql_exception(
sqlalchemy.exc.DatabaseError: (mysql.connector.errors.DatabaseError) 2003 (HY000): Can't connect to MySQL server on 'localhost:3306' (111)
(Background on this error at: https://sqlalche.me/e/20/4xp6)
2025-07-22 21:52:21 - error_handlers - DEBUG - Logger initialized for error_handlers at level DEBUG
2025-07-22 21:52:21 - error_handlers - INFO - Initializing error handling module
2025-07-22 21:52:22 - error_handlers - DEBUG - Logger initialized for error_handlers at level DEBUG
2025-07-22 21:52:22 - error_handlers - INFO - Initializing error handling module
2025-07-22 21:52:22 - error_handlers - DEBUG - Logger initialized for error_handlers at level DEBUG
2025-07-22 21:52:22 - error_handlers - INFO - Initializing error handling module
2025-07-22 21:52:25 - error_handlers - INFO - Initializing error handling module
2025-07-22 21:52:26 - error_handlers - INFO - Initializing error handling module
2025-07-22 21:52:26 - error_handlers - INFO - Initializing error handling module
2025-07-22 21:52:48 - error_handlers - ERROR - Unexpected error: 404 Not Found: The requested URL was not found on the server. If you entered the URL manually please check your spelling and try again.
Traceback (most recent call last):
  File "/www/wwwroot/coinceeper.com/CC/venv/lib64/python3.9/site-packages/flask/app.py", line 917, in full_dispatch_request
    rv = self.dispatch_request()
  File "/www/wwwroot/coinceeper.com/CC/venv/lib64/python3.9/site-packages/flask/app.py", line 891, in dispatch_request
    self.raise_routing_exception(req)
  File "/www/wwwroot/coinceeper.com/CC/venv/lib64/python3.9/site-packages/flask/app.py", line 500, in raise_routing_exception
    raise request.routing_exception  # type: ignore[misc]
  File "/www/wwwroot/coinceeper.com/CC/venv/lib64/python3.9/site-packages/flask/ctx.py", line 362, in match_request
    result = self.url_adapter.match(return_rule=True)  # type: ignore
  File "/www/wwwroot/coinceeper.com/CC/venv/lib64/python3.9/site-packages/werkzeug/routing/map.py", line 629, in match
    raise NotFound() from None
werkzeug.exceptions.NotFound: 404 Not Found: The requested URL was not found on the server. If you entered the URL manually please check your spelling and try again.
2025-07-22 21:52:48 - error_handlers - ERROR - Error traceback: Traceback (most recent call last):
  File "/www/wwwroot/coinceeper.com/CC/venv/lib64/python3.9/site-packages/flask/app.py", line 917, in full_dispatch_request
    rv = self.dispatch_request()
  File "/www/wwwroot/coinceeper.com/CC/venv/lib64/python3.9/site-packages/flask/app.py", line 891, in dispatch_request
    self.raise_routing_exception(req)
  File "/www/wwwroot/coinceeper.com/CC/venv/lib64/python3.9/site-packages/flask/app.py", line 500, in raise_routing_exception
    raise request.routing_exception  # type: ignore[misc]
  File "/www/wwwroot/coinceeper.com/CC/venv/lib64/python3.9/site-packages/flask/ctx.py", line 362, in match_request
    result = self.url_adapter.match(return_rule=True)  # type: ignore
  File "/www/wwwroot/coinceeper.com/CC/venv/lib64/python3.9/site-packages/werkzeug/routing/map.py", line 629, in match
    raise NotFound() from None
werkzeug.exceptions.NotFound: 404 Not Found: The requested URL was not found on the server. If you entered the URL manually please check your spelling and try again.

2025-07-22 22:08:48 - error_handlers - ERROR - Unexpected error: 404 Not Found: The requested URL was not found on the server. If you entered the URL manually please check your spelling and try again.
Traceback (most recent call last):
  File "/www/wwwroot/coinceeper.com/CC/venv/lib64/python3.9/site-packages/flask/app.py", line 917, in full_dispatch_request
    rv = self.dispatch_request()
  File "/www/wwwroot/coinceeper.com/CC/venv/lib64/python3.9/site-packages/flask/app.py", line 891, in dispatch_request
    self.raise_routing_exception(req)
  File "/www/wwwroot/coinceeper.com/CC/venv/lib64/python3.9/site-packages/flask/app.py", line 500, in raise_routing_exception
    raise request.routing_exception  # type: ignore[misc]
  File "/www/wwwroot/coinceeper.com/CC/venv/lib64/python3.9/site-packages/flask/ctx.py", line 362, in match_request
    result = self.url_adapter.match(return_rule=True)  # type: ignore
  File "/www/wwwroot/coinceeper.com/CC/venv/lib64/python3.9/site-packages/werkzeug/routing/map.py", line 629, in match
    raise NotFound() from None
werkzeug.exceptions.NotFound: 404 Not Found: The requested URL was not found on the server. If you entered the URL manually please check your spelling and try again.
2025-07-22 22:08:48 - error_handlers - ERROR - Error traceback: Traceback (most recent call last):
  File "/www/wwwroot/coinceeper.com/CC/venv/lib64/python3.9/site-packages/flask/app.py", line 917, in full_dispatch_request
    rv = self.dispatch_request()
  File "/www/wwwroot/coinceeper.com/CC/venv/lib64/python3.9/site-packages/flask/app.py", line 891, in dispatch_request
    self.raise_routing_exception(req)
  File "/www/wwwroot/coinceeper.com/CC/venv/lib64/python3.9/site-packages/flask/app.py", line 500, in raise_routing_exception
    raise request.routing_exception  # type: ignore[misc]
  File "/www/wwwroot/coinceeper.com/CC/venv/lib64/python3.9/site-packages/flask/ctx.py", line 362, in match_request
    result = self.url_adapter.match(return_rule=True)  # type: ignore
  File "/www/wwwroot/coinceeper.com/CC/venv/lib64/python3.9/site-packages/werkzeug/routing/map.py", line 629, in match
    raise NotFound() from None
werkzeug.exceptions.NotFound: 404 Not Found: The requested URL was not found on the server. If you entered the URL manually please check your spelling and try again.

2025-07-22 22:08:49 - error_handlers - ERROR - Unexpected error: 405 Method Not Allowed: The method is not allowed for the requested URL.
Traceback (most recent call last):
  File "/www/wwwroot/coinceeper.com/CC/venv/lib64/python3.9/site-packages/flask/app.py", line 917, in full_dispatch_request
    rv = self.dispatch_request()
  File "/www/wwwroot/coinceeper.com/CC/venv/lib64/python3.9/site-packages/flask/app.py", line 891, in dispatch_request
    self.raise_routing_exception(req)
  File "/www/wwwroot/coinceeper.com/CC/venv/lib64/python3.9/site-packages/flask/app.py", line 500, in raise_routing_exception
    raise request.routing_exception  # type: ignore[misc]
  File "/www/wwwroot/coinceeper.com/CC/venv/lib64/python3.9/site-packages/flask/ctx.py", line 362, in match_request
    result = self.url_adapter.match(return_rule=True)  # type: ignore
  File "/www/wwwroot/coinceeper.com/CC/venv/lib64/python3.9/site-packages/werkzeug/routing/map.py", line 624, in match
    raise MethodNotAllowed(valid_methods=list(e.have_match_for)) from None
werkzeug.exceptions.MethodNotAllowed: 405 Method Not Allowed: The method is not allowed for the requested URL.
2025-07-22 22:08:49 - error_handlers - ERROR - Error traceback: Traceback (most recent call last):
  File "/www/wwwroot/coinceeper.com/CC/venv/lib64/python3.9/site-packages/flask/app.py", line 917, in full_dispatch_request
    rv = self.dispatch_request()
  File "/www/wwwroot/coinceeper.com/CC/venv/lib64/python3.9/site-packages/flask/app.py", line 891, in dispatch_request
    self.raise_routing_exception(req)
  File "/www/wwwroot/coinceeper.com/CC/venv/lib64/python3.9/site-packages/flask/app.py", line 500, in raise_routing_exception
    raise request.routing_exception  # type: ignore[misc]
  File "/www/wwwroot/coinceeper.com/CC/venv/lib64/python3.9/site-packages/flask/ctx.py", line 362, in match_request
    result = self.url_adapter.match(return_rule=True)  # type: ignore
  File "/www/wwwroot/coinceeper.com/CC/venv/lib64/python3.9/site-packages/werkzeug/routing/map.py", line 624, in match
    raise MethodNotAllowed(valid_methods=list(e.have_match_for)) from None
werkzeug.exceptions.MethodNotAllowed: 405 Method Not Allowed: The method is not allowed for the requested URL.

2025-07-22 22:11:39 - error_handlers - ERROR - Unexpected error: 405 Method Not Allowed: The method is not allowed for the requested URL.
Traceback (most recent call last):
  File "/www/wwwroot/coinceeper.com/CC/venv/lib64/python3.9/site-packages/flask/app.py", line 917, in full_dispatch_request
    rv = self.dispatch_request()
  File "/www/wwwroot/coinceeper.com/CC/venv/lib64/python3.9/site-packages/flask/app.py", line 891, in dispatch_request
    self.raise_routing_exception(req)
  File "/www/wwwroot/coinceeper.com/CC/venv/lib64/python3.9/site-packages/flask/app.py", line 500, in raise_routing_exception
    raise request.routing_exception  # type: ignore[misc]
  File "/www/wwwroot/coinceeper.com/CC/venv/lib64/python3.9/site-packages/flask/ctx.py", line 362, in match_request
    result = self.url_adapter.match(return_rule=True)  # type: ignore
  File "/www/wwwroot/coinceeper.com/CC/venv/lib64/python3.9/site-packages/werkzeug/routing/map.py", line 624, in match
    raise MethodNotAllowed(valid_methods=list(e.have_match_for)) from None
werkzeug.exceptions.MethodNotAllowed: 405 Method Not Allowed: The method is not allowed for the requested URL.
2025-07-22 22:11:39 - error_handlers - ERROR - Error traceback: Traceback (most recent call last):
  File "/www/wwwroot/coinceeper.com/CC/venv/lib64/python3.9/site-packages/flask/app.py", line 917, in full_dispatch_request
    rv = self.dispatch_request()
  File "/www/wwwroot/coinceeper.com/CC/venv/lib64/python3.9/site-packages/flask/app.py", line 891, in dispatch_request
    self.raise_routing_exception(req)
  File "/www/wwwroot/coinceeper.com/CC/venv/lib64/python3.9/site-packages/flask/app.py", line 500, in raise_routing_exception
    raise request.routing_exception  # type: ignore[misc]
  File "/www/wwwroot/coinceeper.com/CC/venv/lib64/python3.9/site-packages/flask/ctx.py", line 362, in match_request
    result = self.url_adapter.match(return_rule=True)  # type: ignore
  File "/www/wwwroot/coinceeper.com/CC/venv/lib64/python3.9/site-packages/werkzeug/routing/map.py", line 624, in match
    raise MethodNotAllowed(valid_methods=list(e.have_match_for)) from None
werkzeug.exceptions.MethodNotAllowed: 405 Method Not Allowed: The method is not allowed for the requested URL.

2025-07-22 22:12:28 - error_handlers - ERROR - Unexpected error: 405 Method Not Allowed: The method is not allowed for the requested URL.
Traceback (most recent call last):
  File "/www/wwwroot/coinceeper.com/CC/venv/lib64/python3.9/site-packages/flask/app.py", line 917, in full_dispatch_request
    rv = self.dispatch_request()
  File "/www/wwwroot/coinceeper.com/CC/venv/lib64/python3.9/site-packages/flask/app.py", line 891, in dispatch_request
    self.raise_routing_exception(req)
  File "/www/wwwroot/coinceeper.com/CC/venv/lib64/python3.9/site-packages/flask/app.py", line 500, in raise_routing_exception
    raise request.routing_exception  # type: ignore[misc]
  File "/www/wwwroot/coinceeper.com/CC/venv/lib64/python3.9/site-packages/flask/ctx.py", line 362, in match_request
    result = self.url_adapter.match(return_rule=True)  # type: ignore
  File "/www/wwwroot/coinceeper.com/CC/venv/lib64/python3.9/site-packages/werkzeug/routing/map.py", line 624, in match
    raise MethodNotAllowed(valid_methods=list(e.have_match_for)) from None
werkzeug.exceptions.MethodNotAllowed: 405 Method Not Allowed: The method is not allowed for the requested URL.
2025-07-22 22:12:28 - error_handlers - ERROR - Error traceback: Traceback (most recent call last):
  File "/www/wwwroot/coinceeper.com/CC/venv/lib64/python3.9/site-packages/flask/app.py", line 917, in full_dispatch_request
    rv = self.dispatch_request()
  File "/www/wwwroot/coinceeper.com/CC/venv/lib64/python3.9/site-packages/flask/app.py", line 891, in dispatch_request
    self.raise_routing_exception(req)
  File "/www/wwwroot/coinceeper.com/CC/venv/lib64/python3.9/site-packages/flask/app.py", line 500, in raise_routing_exception
    raise request.routing_exception  # type: ignore[misc]
  File "/www/wwwroot/coinceeper.com/CC/venv/lib64/python3.9/site-packages/flask/ctx.py", line 362, in match_request
    result = self.url_adapter.match(return_rule=True)  # type: ignore
  File "/www/wwwroot/coinceeper.com/CC/venv/lib64/python3.9/site-packages/werkzeug/routing/map.py", line 624, in match
    raise MethodNotAllowed(valid_methods=list(e.have_match_for)) from None
werkzeug.exceptions.MethodNotAllowed: 405 Method Not Allowed: The method is not allowed for the requested URL.

2025-07-22 22:12:29 - error_handlers - ERROR - Unexpected error: 405 Method Not Allowed: The method is not allowed for the requested URL.
Traceback (most recent call last):
  File "/www/wwwroot/coinceeper.com/CC/venv/lib64/python3.9/site-packages/flask/app.py", line 917, in full_dispatch_request
    rv = self.dispatch_request()
  File "/www/wwwroot/coinceeper.com/CC/venv/lib64/python3.9/site-packages/flask/app.py", line 891, in dispatch_request
    self.raise_routing_exception(req)
  File "/www/wwwroot/coinceeper.com/CC/venv/lib64/python3.9/site-packages/flask/app.py", line 500, in raise_routing_exception
    raise request.routing_exception  # type: ignore[misc]
  File "/www/wwwroot/coinceeper.com/CC/venv/lib64/python3.9/site-packages/flask/ctx.py", line 362, in match_request
    result = self.url_adapter.match(return_rule=True)  # type: ignore
  File "/www/wwwroot/coinceeper.com/CC/venv/lib64/python3.9/site-packages/werkzeug/routing/map.py", line 624, in match
    raise MethodNotAllowed(valid_methods=list(e.have_match_for)) from None
werkzeug.exceptions.MethodNotAllowed: 405 Method Not Allowed: The method is not allowed for the requested URL.
2025-07-22 22:12:29 - error_handlers - ERROR - Error traceback: Traceback (most recent call last):
  File "/www/wwwroot/coinceeper.com/CC/venv/lib64/python3.9/site-packages/flask/app.py", line 917, in full_dispatch_request
    rv = self.dispatch_request()
  File "/www/wwwroot/coinceeper.com/CC/venv/lib64/python3.9/site-packages/flask/app.py", line 891, in dispatch_request
    self.raise_routing_exception(req)
  File "/www/wwwroot/coinceeper.com/CC/venv/lib64/python3.9/site-packages/flask/app.py", line 500, in raise_routing_exception
    raise request.routing_exception  # type: ignore[misc]
  File "/www/wwwroot/coinceeper.com/CC/venv/lib64/python3.9/site-packages/flask/ctx.py", line 362, in match_request
    result = self.url_adapter.match(return_rule=True)  # type: ignore
  File "/www/wwwroot/coinceeper.com/CC/venv/lib64/python3.9/site-packages/werkzeug/routing/map.py", line 624, in match
    raise MethodNotAllowed(valid_methods=list(e.have_match_for)) from None
werkzeug.exceptions.MethodNotAllowed: 405 Method Not Allowed: The method is not allowed for the requested URL.

2025-07-22 22:12:32 - error_handlers - ERROR - Unexpected error: 405 Method Not Allowed: The method is not allowed for the requested URL.
Traceback (most recent call last):
  File "/www/wwwroot/coinceeper.com/CC/venv/lib64/python3.9/site-packages/flask/app.py", line 917, in full_dispatch_request
    rv = self.dispatch_request()
  File "/www/wwwroot/coinceeper.com/CC/venv/lib64/python3.9/site-packages/flask/app.py", line 891, in dispatch_request
    self.raise_routing_exception(req)
  File "/www/wwwroot/coinceeper.com/CC/venv/lib64/python3.9/site-packages/flask/app.py", line 500, in raise_routing_exception
    raise request.routing_exception  # type: ignore[misc]
  File "/www/wwwroot/coinceeper.com/CC/venv/lib64/python3.9/site-packages/flask/ctx.py", line 362, in match_request
    result = self.url_adapter.match(return_rule=True)  # type: ignore
  File "/www/wwwroot/coinceeper.com/CC/venv/lib64/python3.9/site-packages/werkzeug/routing/map.py", line 624, in match
    raise MethodNotAllowed(valid_methods=list(e.have_match_for)) from None
werkzeug.exceptions.MethodNotAllowed: 405 Method Not Allowed: The method is not allowed for the requested URL.
2025-07-22 22:12:32 - error_handlers - ERROR - Error traceback: Traceback (most recent call last):
  File "/www/wwwroot/coinceeper.com/CC/venv/lib64/python3.9/site-packages/flask/app.py", line 917, in full_dispatch_request
    rv = self.dispatch_request()
  File "/www/wwwroot/coinceeper.com/CC/venv/lib64/python3.9/site-packages/flask/app.py", line 891, in dispatch_request
    self.raise_routing_exception(req)
  File "/www/wwwroot/coinceeper.com/CC/venv/lib64/python3.9/site-packages/flask/app.py", line 500, in raise_routing_exception
    raise request.routing_exception  # type: ignore[misc]
  File "/www/wwwroot/coinceeper.com/CC/venv/lib64/python3.9/site-packages/flask/ctx.py", line 362, in match_request
    result = self.url_adapter.match(return_rule=True)  # type: ignore
  File "/www/wwwroot/coinceeper.com/CC/venv/lib64/python3.9/site-packages/werkzeug/routing/map.py", line 624, in match
    raise MethodNotAllowed(valid_methods=list(e.have_match_for)) from None
werkzeug.exceptions.MethodNotAllowed: 405 Method Not Allowed: The method is not allowed for the requested URL.

2025-07-22 22:15:47 - error_handlers - ERROR - Unexpected error: 404 Not Found: The requested URL was not found on the server. If you entered the URL manually please check your spelling and try again.
Traceback (most recent call last):
  File "/www/wwwroot/coinceeper.com/CC/venv/lib64/python3.9/site-packages/flask/app.py", line 917, in full_dispatch_request
    rv = self.dispatch_request()
  File "/www/wwwroot/coinceeper.com/CC/venv/lib64/python3.9/site-packages/flask/app.py", line 891, in dispatch_request
    self.raise_routing_exception(req)
  File "/www/wwwroot/coinceeper.com/CC/venv/lib64/python3.9/site-packages/flask/app.py", line 500, in raise_routing_exception
    raise request.routing_exception  # type: ignore[misc]
  File "/www/wwwroot/coinceeper.com/CC/venv/lib64/python3.9/site-packages/flask/ctx.py", line 362, in match_request
    result = self.url_adapter.match(return_rule=True)  # type: ignore
  File "/www/wwwroot/coinceeper.com/CC/venv/lib64/python3.9/site-packages/werkzeug/routing/map.py", line 629, in match
    raise NotFound() from None
werkzeug.exceptions.NotFound: 404 Not Found: The requested URL was not found on the server. If you entered the URL manually please check your spelling and try again.
2025-07-22 22:15:47 - error_handlers - ERROR - Error traceback: Traceback (most recent call last):
  File "/www/wwwroot/coinceeper.com/CC/venv/lib64/python3.9/site-packages/flask/app.py", line 917, in full_dispatch_request
    rv = self.dispatch_request()
  File "/www/wwwroot/coinceeper.com/CC/venv/lib64/python3.9/site-packages/flask/app.py", line 891, in dispatch_request
    self.raise_routing_exception(req)
  File "/www/wwwroot/coinceeper.com/CC/venv/lib64/python3.9/site-packages/flask/app.py", line 500, in raise_routing_exception
    raise request.routing_exception  # type: ignore[misc]
  File "/www/wwwroot/coinceeper.com/CC/venv/lib64/python3.9/site-packages/flask/ctx.py", line 362, in match_request
    result = self.url_adapter.match(return_rule=True)  # type: ignore
  File "/www/wwwroot/coinceeper.com/CC/venv/lib64/python3.9/site-packages/werkzeug/routing/map.py", line 629, in match
    raise NotFound() from None
werkzeug.exceptions.NotFound: 404 Not Found: The requested URL was not found on the server. If you entered the URL manually please check your spelling and try again.

2025-07-22 22:16:00 - error_handlers - ERROR - Unexpected error: 404 Not Found: The requested URL was not found on the server. If you entered the URL manually please check your spelling and try again.
Traceback (most recent call last):
  File "/www/wwwroot/coinceeper.com/CC/venv/lib64/python3.9/site-packages/flask/app.py", line 917, in full_dispatch_request
    rv = self.dispatch_request()
  File "/www/wwwroot/coinceeper.com/CC/venv/lib64/python3.9/site-packages/flask/app.py", line 891, in dispatch_request
    self.raise_routing_exception(req)
  File "/www/wwwroot/coinceeper.com/CC/venv/lib64/python3.9/site-packages/flask/app.py", line 500, in raise_routing_exception
    raise request.routing_exception  # type: ignore[misc]
  File "/www/wwwroot/coinceeper.com/CC/venv/lib64/python3.9/site-packages/flask/ctx.py", line 362, in match_request
    result = self.url_adapter.match(return_rule=True)  # type: ignore
  File "/www/wwwroot/coinceeper.com/CC/venv/lib64/python3.9/site-packages/werkzeug/routing/map.py", line 629, in match
    raise NotFound() from None
werkzeug.exceptions.NotFound: 404 Not Found: The requested URL was not found on the server. If you entered the URL manually please check your spelling and try again.
2025-07-22 22:16:00 - error_handlers - ERROR - Error traceback: Traceback (most recent call last):
  File "/www/wwwroot/coinceeper.com/CC/venv/lib64/python3.9/site-packages/flask/app.py", line 917, in full_dispatch_request
    rv = self.dispatch_request()
  File "/www/wwwroot/coinceeper.com/CC/venv/lib64/python3.9/site-packages/flask/app.py", line 891, in dispatch_request
    self.raise_routing_exception(req)
  File "/www/wwwroot/coinceeper.com/CC/venv/lib64/python3.9/site-packages/flask/app.py", line 500, in raise_routing_exception
    raise request.routing_exception  # type: ignore[misc]
  File "/www/wwwroot/coinceeper.com/CC/venv/lib64/python3.9/site-packages/flask/ctx.py", line 362, in match_request
    result = self.url_adapter.match(return_rule=True)  # type: ignore
  File "/www/wwwroot/coinceeper.com/CC/venv/lib64/python3.9/site-packages/werkzeug/routing/map.py", line 629, in match
    raise NotFound() from None
werkzeug.exceptions.NotFound: 404 Not Found: The requested URL was not found on the server. If you entered the URL manually please check your spelling and try again.

2025-07-22 22:16:01 - error_handlers - ERROR - Unexpected error: 404 Not Found: The requested URL was not found on the server. If you entered the URL manually please check your spelling and try again.
Traceback (most recent call last):
  File "/www/wwwroot/coinceeper.com/CC/venv/lib64/python3.9/site-packages/flask/app.py", line 917, in full_dispatch_request
    rv = self.dispatch_request()
  File "/www/wwwroot/coinceeper.com/CC/venv/lib64/python3.9/site-packages/flask/app.py", line 891, in dispatch_request
    self.raise_routing_exception(req)
  File "/www/wwwroot/coinceeper.com/CC/venv/lib64/python3.9/site-packages/flask/app.py", line 500, in raise_routing_exception
    raise request.routing_exception  # type: ignore[misc]
  File "/www/wwwroot/coinceeper.com/CC/venv/lib64/python3.9/site-packages/flask/ctx.py", line 362, in match_request
    result = self.url_adapter.match(return_rule=True)  # type: ignore
  File "/www/wwwroot/coinceeper.com/CC/venv/lib64/python3.9/site-packages/werkzeug/routing/map.py", line 629, in match
    raise NotFound() from None
werkzeug.exceptions.NotFound: 404 Not Found: The requested URL was not found on the server. If you entered the URL manually please check your spelling and try again.
2025-07-22 22:16:01 - error_handlers - ERROR - Error traceback: Traceback (most recent call last):
  File "/www/wwwroot/coinceeper.com/CC/venv/lib64/python3.9/site-packages/flask/app.py", line 917, in full_dispatch_request
    rv = self.dispatch_request()
  File "/www/wwwroot/coinceeper.com/CC/venv/lib64/python3.9/site-packages/flask/app.py", line 891, in dispatch_request
    self.raise_routing_exception(req)
  File "/www/wwwroot/coinceeper.com/CC/venv/lib64/python3.9/site-packages/flask/app.py", line 500, in raise_routing_exception
    raise request.routing_exception  # type: ignore[misc]
  File "/www/wwwroot/coinceeper.com/CC/venv/lib64/python3.9/site-packages/flask/ctx.py", line 362, in match_request
    result = self.url_adapter.match(return_rule=True)  # type: ignore
  File "/www/wwwroot/coinceeper.com/CC/venv/lib64/python3.9/site-packages/werkzeug/routing/map.py", line 629, in match
    raise NotFound() from None
werkzeug.exceptions.NotFound: 404 Not Found: The requested URL was not found on the server. If you entered the URL manually please check your spelling and try again.

2025-07-22 22:22:02 - error_handlers - ERROR - Unexpected error: 404 Not Found: The requested URL was not found on the server. If you entered the URL manually please check your spelling and try again.
Traceback (most recent call last):
  File "/www/wwwroot/coinceeper.com/CC/venv/lib64/python3.9/site-packages/flask/app.py", line 917, in full_dispatch_request
    rv = self.dispatch_request()
  File "/www/wwwroot/coinceeper.com/CC/venv/lib64/python3.9/site-packages/flask/app.py", line 891, in dispatch_request
    self.raise_routing_exception(req)
  File "/www/wwwroot/coinceeper.com/CC/venv/lib64/python3.9/site-packages/flask/app.py", line 500, in raise_routing_exception
    raise request.routing_exception  # type: ignore[misc]
  File "/www/wwwroot/coinceeper.com/CC/venv/lib64/python3.9/site-packages/flask/ctx.py", line 362, in match_request
    result = self.url_adapter.match(return_rule=True)  # type: ignore
  File "/www/wwwroot/coinceeper.com/CC/venv/lib64/python3.9/site-packages/werkzeug/routing/map.py", line 629, in match
    raise NotFound() from None
werkzeug.exceptions.NotFound: 404 Not Found: The requested URL was not found on the server. If you entered the URL manually please check your spelling and try again.
2025-07-22 22:22:02 - error_handlers - ERROR - Error traceback: Traceback (most recent call last):
  File "/www/wwwroot/coinceeper.com/CC/venv/lib64/python3.9/site-packages/flask/app.py", line 917, in full_dispatch_request
    rv = self.dispatch_request()
  File "/www/wwwroot/coinceeper.com/CC/venv/lib64/python3.9/site-packages/flask/app.py", line 891, in dispatch_request
    self.raise_routing_exception(req)
  File "/www/wwwroot/coinceeper.com/CC/venv/lib64/python3.9/site-packages/flask/app.py", line 500, in raise_routing_exception
    raise request.routing_exception  # type: ignore[misc]
  File "/www/wwwroot/coinceeper.com/CC/venv/lib64/python3.9/site-packages/flask/ctx.py", line 362, in match_request
    result = self.url_adapter.match(return_rule=True)  # type: ignore
  File "/www/wwwroot/coinceeper.com/CC/venv/lib64/python3.9/site-packages/werkzeug/routing/map.py", line 629, in match
    raise NotFound() from None
werkzeug.exceptions.NotFound: 404 Not Found: The requested URL was not found on the server. If you entered the URL manually please check your spelling and try again.

2025-07-22 23:09:11 - error_handlers - ERROR - Unexpected error: 404 Not Found: The requested URL was not found on the server. If you entered the URL manually please check your spelling and try again.
Traceback (most recent call last):
  File "/www/wwwroot/coinceeper.com/CC/venv/lib64/python3.9/site-packages/flask/app.py", line 917, in full_dispatch_request
    rv = self.dispatch_request()
  File "/www/wwwroot/coinceeper.com/CC/venv/lib64/python3.9/site-packages/flask/app.py", line 891, in dispatch_request
    self.raise_routing_exception(req)
  File "/www/wwwroot/coinceeper.com/CC/venv/lib64/python3.9/site-packages/flask/app.py", line 500, in raise_routing_exception
    raise request.routing_exception  # type: ignore[misc]
  File "/www/wwwroot/coinceeper.com/CC/venv/lib64/python3.9/site-packages/flask/ctx.py", line 362, in match_request
    result = self.url_adapter.match(return_rule=True)  # type: ignore
  File "/www/wwwroot/coinceeper.com/CC/venv/lib64/python3.9/site-packages/werkzeug/routing/map.py", line 629, in match
    raise NotFound() from None
werkzeug.exceptions.NotFound: 404 Not Found: The requested URL was not found on the server. If you entered the URL manually please check your spelling and try again.
2025-07-22 23:09:11 - error_handlers - ERROR - Error traceback: Traceback (most recent call last):
  File "/www/wwwroot/coinceeper.com/CC/venv/lib64/python3.9/site-packages/flask/app.py", line 917, in full_dispatch_request
    rv = self.dispatch_request()
  File "/www/wwwroot/coinceeper.com/CC/venv/lib64/python3.9/site-packages/flask/app.py", line 891, in dispatch_request
    self.raise_routing_exception(req)
  File "/www/wwwroot/coinceeper.com/CC/venv/lib64/python3.9/site-packages/flask/app.py", line 500, in raise_routing_exception
    raise request.routing_exception  # type: ignore[misc]
  File "/www/wwwroot/coinceeper.com/CC/venv/lib64/python3.9/site-packages/flask/ctx.py", line 362, in match_request
    result = self.url_adapter.match(return_rule=True)  # type: ignore
  File "/www/wwwroot/coinceeper.com/CC/venv/lib64/python3.9/site-packages/werkzeug/routing/map.py", line 629, in match
    raise NotFound() from None
werkzeug.exceptions.NotFound: 404 Not Found: The requested URL was not found on the server. If you entered the URL manually please check your spelling and try again.

2025-07-22 23:09:23 - error_handlers - ERROR - Unexpected error: 404 Not Found: The requested URL was not found on the server. If you entered the URL manually please check your spelling and try again.
Traceback (most recent call last):
  File "/www/wwwroot/coinceeper.com/CC/venv/lib64/python3.9/site-packages/flask/app.py", line 917, in full_dispatch_request
    rv = self.dispatch_request()
  File "/www/wwwroot/coinceeper.com/CC/venv/lib64/python3.9/site-packages/flask/app.py", line 891, in dispatch_request
    self.raise_routing_exception(req)
  File "/www/wwwroot/coinceeper.com/CC/venv/lib64/python3.9/site-packages/flask/app.py", line 500, in raise_routing_exception
    raise request.routing_exception  # type: ignore[misc]
  File "/www/wwwroot/coinceeper.com/CC/venv/lib64/python3.9/site-packages/flask/ctx.py", line 362, in match_request
    result = self.url_adapter.match(return_rule=True)  # type: ignore
  File "/www/wwwroot/coinceeper.com/CC/venv/lib64/python3.9/site-packages/werkzeug/routing/map.py", line 629, in match
    raise NotFound() from None
werkzeug.exceptions.NotFound: 404 Not Found: The requested URL was not found on the server. If you entered the URL manually please check your spelling and try again.
2025-07-22 23:09:23 - error_handlers - ERROR - Error traceback: Traceback (most recent call last):
  File "/www/wwwroot/coinceeper.com/CC/venv/lib64/python3.9/site-packages/flask/app.py", line 917, in full_dispatch_request
    rv = self.dispatch_request()
  File "/www/wwwroot/coinceeper.com/CC/venv/lib64/python3.9/site-packages/flask/app.py", line 891, in dispatch_request
    self.raise_routing_exception(req)
  File "/www/wwwroot/coinceeper.com/CC/venv/lib64/python3.9/site-packages/flask/app.py", line 500, in raise_routing_exception
    raise request.routing_exception  # type: ignore[misc]
  File "/www/wwwroot/coinceeper.com/CC/venv/lib64/python3.9/site-packages/flask/ctx.py", line 362, in match_request
    result = self.url_adapter.match(return_rule=True)  # type: ignore
  File "/www/wwwroot/coinceeper.com/CC/venv/lib64/python3.9/site-packages/werkzeug/routing/map.py", line 629, in match
    raise NotFound() from None
werkzeug.exceptions.NotFound: 404 Not Found: The requested URL was not found on the server. If you entered the URL manually please check your spelling and try again.

